Workbook

Sheet 00_อ่านก่อน
B2: CI/CD Resource & Compliance Planner
B3: ตารางเครื่องมือ CI/CD ทุกประเภท + การคำนวณทรัพยากรกรณีเครื่องแชร์ + ผลลัพธ์ระยะยาว
B4: Schema 1.2.0 — ใช้เป็นแบบฟอร์มกลางสำหรับประเมินโครงการใด ๆ (ไม่มีข้อมูลเฉพาะโครงการอยู่ในไฟล์นี้)
B6: ชีทในไฟล์นี้
B7: 05_Params | C7: พารามิเตอร์ทั้งหมดของโมเดล — เปลี่ยนโหมด strict/realistic, Scale Factor, OS Reserve, ช่วงเวลาประเมิน (ช่องสีเหลืองคือช่องที่แก้ได้)
B8: 01_Tool_Catalog | C8: ตารางเครื่องมือ 72 รายการ ครบ 6 Stage พร้อม minimum vCPU/RAM/Disk, ที่มาของตัวเลข, มาตรฐานไทย/สากลที่แต่ละเครื่องมือช่วยตอบ, ทางเลือก Enterprise/OSS และข้อควรระวัง
B9: 02_Freq_Weight | C9: ชั้นความถี่การรัน 7 ระดับ และการแปลงเป็นน้ำหนัก 50%-95%
B10: 03_Colocation_Calc | C10: ตารางกำหนดว่าเครื่องมือใดติดตั้งบน VM ใด (ใส่ 1/0) — เป็นช่องกรอกหลัก
B11: 04_VM_Sizing | C11: ผลการคำนวณต่อ VM: เงื่อนไข A / B1 / B2 / C, ค่าที่ต้องจัดสรร, และส่วนต่างกับ spec จริง
B12: 06_Storage_LongTerm | C12: ผลลัพธ์ระยะยาวของพื้นที่จัดเก็บที่ 12 / 24 / 36 / 60 เดือน + สิ่งที่ต้องทำเพื่อคุมการโต
B13: 07_Compliance_Matrix | C13: มาตรการที่ต้องทำ 50 รายการ พร้อมสถานะผ่าน/ไม่ผ่าน และเลขข้อของมาตรฐานที่อ้างแต่ละมาตรการ
B14: 08_Tool_Capability | C14: เมทริกซ์เครื่องมือ x capability (ฐานคำนวณของชีท 07)
B15: 09_Profile_Comparison | C15: เปรียบเทียบประเภทโครงการ 5 แบบ
B16: 10_Archetypes | C16: ผังเครื่องอ้างอิง 4 แบบ (2 / 4 / 6 เครื่อง และ AI/ML) พร้อมชุดเครื่องมือตามบทบาท — ใช้เป็นจุดตั้งต้นของโครงการใหม่
B17: 11_Frameworks | C17: ทะเบียนกฎหมายและมาตรฐาน 48 ฉบับ แยกไทย/สากล พร้อมเมทริกซ์ว่าฉบับใดอ้างมาตรการใด (เลขข้ออยู่ใน comment ของช่อง)
B19: วิธีใช้
B20: ขั้นที่ 1 | C20: เปิดชีท 05_Params เลือกโหมดการคำนวณและ Scale Factor ให้ตรงกับขนาดงานจริง
B21: ขั้นที่ 2 | C21: เลือกผังตั้งต้นจากชีท 10_Archetypes แล้วเปิดชีท 03_Colocation_Calc ใส่ 1 ในคอลัมน์ VM ที่จะติดตั้งเครื่องมือนั้น (VM01-06 ใส่ผังอ้างอิงภาครัฐ 6 เครื่องไว้ให้แล้ว, VM07-10 ว่างสำหรับกรณีอื่น)
B22: ขั้นที่ 3 | C22: ดูผลที่ชีท 04_VM_Sizing — คอลัมน์ 'จัดสรร' คือค่า minimum ที่ต้องขอ และคอลัมน์ 'ผลประเมิน' บอกว่า spec ที่ขอไว้พอหรือไม่
B23: ขั้นที่ 4 | C23: ตรวจ compliance ที่ชีท 07_Compliance_Matrix — ข้อที่ 'ไม่ผ่าน' คือ capability ที่ยังไม่มีเครื่องมือรองรับ
B24: ขั้นที่ 5 | C24: วางแผนพื้นที่จัดเก็บระยะยาวจากชีท 06_Storage_LongTerm
B26: รหัสสีที่ใช้
B27: ตัวเลขสีน้ำเงิน + พื้นเหลือง | C27: ช่องที่ผู้ใช้กรอก/แก้ไขได้
B28: ตัวเลขสีเขียว | C28: สูตรที่อ้างอิงข้ามชีท
B29: ตัวเลขสีดำ | C29: สูตรคำนวณภายในชีทเดียวกัน
B30: พื้นเขียวอ่อน | C30: ผลลัพธ์สุดท้ายที่ต้องนำไปใช้ขอทรัพยากร
B31: พื้นสีตาม Stage | C31: ฟ้า=Stage 1, เหลือง=2, ส้ม=3, เขียว=4, ม่วง=5, พีช=6
B33: ข้อจำกัดที่ต้องรู้ก่อนใช้ตัวเลขนี้
B34: 1 | C34: ตัวเลข minimum เป็นค่าตั้งต้นจากเอกสารติดตั้งของผู้พัฒนาแต่ละเครื่องมือ รวมกับค่าที่พบจากการใช้งานจริงระดับ UAT/Production ขนาดเล็ก ไม่ใช่ผลวัดจากระบบของท่าน — ต้องวัด baseline จริง 2-4 สัปดาห์แล้วปรับ
B35: 2 | C35: โหมด strict (ตามโจทย์) จะได้ค่าสูงกว่าความเป็นจริงในเครื่องที่มีเครื่องมือ ephemeral จำนวนมาก เพราะบวกทุกตัวแม้ในความจริงจะรันเรียงต่อกัน — ใช้ยื่นขอทรัพยากรเพื่อความปลอดภัย และใช้โหมด realistic เพื่อดูค่าที่น่าจะเกิดขึ้นจริง
B36: 3 | C36: ปริมาณข้อมูลต่อวันอ่อนไหวต่อระดับ log และจำนวน build มาก — เปลี่ยน Scale Factor ให้ตรงกับปริมาณจริงก่อนอ่านผลชีท 06
B37: 3.1 | C37: คอลัมน์มาตรฐานในชีท 01 บอกว่าเครื่องมือ 'ช่วยตอบ' ข้อกำหนดใดได้ ไม่ได้รับประกันว่าตั้งค่าถูกต้อง — การผ่านมาตรฐานจริงยังต้องมีการตั้งค่า กระบวนการ และหลักฐานการตรวจสอบประกอบ
B38: 4 | C38: ตารางนี้ไม่ครอบคลุม network bandwidth, IOPS และ license cost ซึ่งต้องประเมินแยก
B39: 5 | C39: License ที่เป็น GPL/AGPL (MinIO, Grafana, Zabbix, FOSSology, Wazuh, testssl.sh) ขัดกับข้อห้ามของโครงการภาครัฐบางแห่ง — ต้องตรวจเงื่อนไขการใช้งานก่อน

Sheet 01_Tool_Catalog
A1: 01 — ตารางเครื่องมือ CI/CD ทุกประเภท + Resource Requirements (Minimum) | C1: 72 เครื่องมือ ครบ 6 Stage ตาม CI/CD Service Blueprint V0.2
A2: tool_id | B2: เครื่องมือ | C2: Stage | D2: หมวด (ขั้นตอนย่อย) | E2: Core/Opt | F2: Grade | G2: License | H2: min vCPU | I2: min RAM (GB) | J2: min Disk OS (GB) | K2: rec vCPU | L2: rec RAM (GB) | M2: rec Disk OS (GB) | N2: Resident 24/7 | O2: Idle RAM (GB) | P2: Conc Group | Q2: freq_id | R2: น้ำหนัก w | S2: Data GB/วัน | T2: Retention (วัน) | U2: Index OH | V2: Growth/ปี | W2: Capabilities ที่ตอบได้ | X2: มาตรฐานไทยที่ช่วยตอบ | Y2: มาตรฐานสากลที่ช่วยตอบ | Z2: มาตรการที่ตอบได้ครบด้วยตัวเอง | AA2: มาตรการที่ช่วยตอบบางส่วน | AB2: จำนวน มาตรการ | AC2: ทางเลือก Enterprise-Grade | AD2: ทางเลือก Open Source อื่น | AE2: ที่มาของตัวเลข Minimum (Sizing Reference) | AF2: ข้อสังเกต / ข้อควรระวังในการวางเครื่อง
A3: gitlab-ce | B3: GitLab Community Edition (Self-hosted Git) | C3: 1 | D3: Git Repository | E3: Core | F3: oss | G3: MIT | H3: 4 | I3: 8 | J3: 40 | K3: 8 | L3: 16 | M3: 200 | N3: 1 | O3: 5 | P3: resident | Q3: resident | R3: =INDEX('02_Freq_Weight'!$E$3:$E$9,MATCH(Q3,'02_Freq_Weight'!$A$3:$A$9,0)) | S3: 0.05 | T3: 3650 | U3: 0.2 | V3: 0.25 | W3: git_scm, webhook, branch_protection, pipeline, audit_trail | X3: พ.ร.บ. คอมพิวเตอร์ 2550/2560; พ.ร.บ. ไซเบอร์ 2562; มาตรฐานข้อมูลเปิดภาครัฐ; พ.ร.บ. ปฏิบัติราชการทางอิเล็กทรอนิกส์ 2565; ขมธอ. ลายมือชื่อ/เอกสารอิเล็กทรอนิกส์; ITA (ป.ป.ช.); มาตรฐานขั้นต่ำ 2566; กรอบมาตรฐานไซเบอร์ 2564; มาตรฐานเว็บไซต์ 2568; PDPA 2562 | Y3: ISO 22301:2019; ISO/IEC 27001:2022; ISO/IEC 27018; ISO/IEC 27701; ISO/IEC 42001:2023; NIST SP 800-53r5; NIST CSF 2.0; NIST SSDF (SP 800-218); OWASP SAMM 2; SLSA v1.0; SOC 2 (TSC) | Z3: C-LOG-AUDIT | AA3: C-LOG-90, C-OPS-BCP, C-SDLC-REVIEW, C-SDLC-TRACE, C-WEB-SELF | AB3: 6 | AC3: GitLab Enterprise Edition; GitHub Enterprise Server; Bitbucket Data Center; Azure DevOps Server | AD3: Gitea; Forgejo; Gogs; Onedev | AE3: GitLab docs: 4 vCPU / 4 GB (แนะนำ 8 GB) รองรับได้ถึง ~500 users; Puma+Sidekiq+Gitaly+PostgreSQL+Redis รวมในเครื่องเดียว | AF3: ทางเลือกหลักของภาครัฐที่ต้องการ Git แบบ On-premise เต็มรูปแบบ กินทรัพยากรมากเพราะรวมหลาย service; ถ้าต้องการเบาให้ใช้ Gitea
A4: gitea | B4: Gitea / Forgejo (Lightweight Git) | C4: 1 | D4: Git Repository | E4: Core | F4: oss | G4: MIT | H4: 1 | I4: 1 | J4: 10 | K4: 2 | L4: 4 | M4: 100 | N4: 1 | O4: 0.5 | P4: resident | Q4: resident | R4: =INDEX('02_Freq_Weight'!$E$3:$E$9,MATCH(Q4,'02_Freq_Weight'!$A$3:$A$9,0)) | S4: 0.02 | T4: 3650 | U4: 0.1 | V4: 0.25 | W4: git_scm, webhook, branch_protection, audit_trail | X4: พ.ร.บ. คอมพิวเตอร์ 2550/2560; พ.ร.บ. ไซเบอร์ 2562; มาตรฐานข้อมูลเปิดภาครัฐ; พ.ร.บ. ปฏิบัติราชการทางอิเล็กทรอนิกส์ 2565; ขมธอ. ลายมือชื่อ/เอกสารอิเล็กทรอนิกส์; ITA (ป.ป.ช.); มาตรฐานขั้นต่ำ 2566; กรอบมาตรฐานไซเบอร์ 2564; มาตรฐานเว็บไซต์ 2568; PDPA 2562 | Y4: ISO 22301:2019; ISO/IEC 27001:2022; ISO/IEC 27018; ISO/IEC 27701; ISO/IEC 42001:2023; NIST SP 800-53r5; NIST CSF 2.0; NIST SSDF (SP 800-218); OWASP SAMM 2; SLSA v1.0; SOC 2 (TSC) | Z4: C-LOG-AUDIT | AA4: C-LOG-90, C-OPS-BCP, C-SDLC-REVIEW, C-SDLC-TRACE, C-WEB-SELF | AB4: 6 | AC4: GitLab Enterprise Edition; GitHub Enterprise Server; Bitbucket Data Center | AE4: Gitea docs: 2 CPU cores / 1 GB RAM เพียงพอสำหรับทีมขนาดเล็ก-กลาง; binary เดียว + SQLite/PostgreSQL | AF4: ตัวเลือกเบาสำหรับเครื่องที่ต้องแชร์กับเครื่องมืออื่น กินแค่ ~300-500 MB RAM ตอน idle
A5: github-actions-runner | B5: GitHub Actions Self-hosted Runner | C5: 1 | D5: Pipeline Orchestration | E5: Core | F5: oss | G5: MIT | H5: 2 | I5: 4 | J5: 60 | K5: 4 | L5: 8 | M5: 150 | N5: 0 | O5: 0.2 | P5: ci_seq | Q5: per_commit | R5: =INDEX('02_Freq_Weight'!$E$3:$E$9,MATCH(Q5,'02_Freq_Weight'!$A$3:$A$9,0)) | S5: 0.6 | T5: 30 | U5: 0.05 | V5: 0.2 | W5: pipeline, webhook, build | X5: มาตรฐานข้อมูลเปิดภาครัฐ; พ.ร.บ. ปฏิบัติราชการทางอิเล็กทรอนิกส์ 2565 | Y5: CIS Benchmarks; NIST SSDF (SP 800-218); OWASP Top 10:2025; SLSA v1.0 | Z5: - | AA5: C-SC-IMG, C-SC-PIN, C-SDLC-TRACE | AB5: 3 | AC5: GitHub Actions Enterprise; GitHub Enterprise Server | AE5: GitHub-hosted standard runner = 2 vCPU / 7 GB / 14 GB SSD — ใช้เป็นเกณฑ์เทียบขั้นต่ำของ self-hosted runner | AF5: รูปแบบที่ประหยัดที่สุดคือให้ Runner ของผู้ให้บริการ Git ทำงานเบา (Lint / Unit Test) แล้วส่ง Webhook เข้า Orchestrator ในองค์กร จึงไม่ต้องใช้ VM ของหน่วยงานในขั้นนี้; ถ้าอยู่หลัง Proxy ต้อง whitelist โดเมนของผู้ให้บริการ (เช่น *.github.com, *.ghcr.io, *.githubusercontent.com)
A6: jenkins-master | B6: Jenkins Master / Controller | C6: 1 | D6: Pipeline Orchestration | E6: Core | F6: oss | G6: MIT | H6: 2 | I6: 4 | J6: 20 | K6: 4 | L6: 8 | M6: 100 | N6: 1 | O6: 2 | P6: resident | Q6: resident | R6: =INDEX('02_Freq_Weight'!$E$3:$E$9,MATCH(Q6,'02_Freq_Weight'!$A$3:$A$9,0)) | S6: 0.15 | T6: 180 | U6: 0.1 | V6: 0.15 | W6: pipeline, webhook, quality_gate, audit_trail, notify | X6: พ.ร.บ. คอมพิวเตอร์ 2550/2560; พ.ร.บ. ไซเบอร์ 2562; มาตรฐานข้อมูลเปิดภาครัฐ; พ.ร.บ. ปฏิบัติราชการทางอิเล็กทรอนิกส์ 2565; ขมธอ. ลายมือชื่อ/เอกสารอิเล็กทรอนิกส์; ITA (ป.ป.ช.); มาตรฐานขั้นต่ำ 2566; กรอบมาตรฐานไซเบอร์ 2564; มาตรฐานเว็บไซต์ 2568; PDPA 2562; ประกาศ PDPC แจ้งเหตุละเมิด 2565 | Y6: ISO 22301:2019; ISO/IEC 27001:2022; ISO/IEC 27018; ISO/IEC 27034; ISO/IEC 27701; ISO/IEC 42001:2023; NIST SP 800-53r5; NIST CSF 2.0; NIST SSDF (SP 800-218); OWASP SAMM 2; OWASP Top 10:2025; SLSA v1.0; SOC 2 (TSC) | Z6: C-LOG-AUDIT | AA6: C-AI-GOV, C-LOG-90, C-LOG-NOTIFY, C-OPS-BCP, C-PRV-BREACH, C-SDLC-REVIEW, C-SDLC-THREAT, C-SDLC-TRACE, C-WEB-SELF | AB6: 10 | AC6: CloudBees CI; Jenkins Enterprise; Azure DevOps Server; GitLab Ultimate Self-Managed | AD6: Argo Workflows; Tekton Pipelines; Woodpecker CI; Drone CI; Concourse CI | AE6: Jenkins docs: absolute min 256 MB RAM / 1 GB disk; 'small team' 1 GB+ RAM / 50 GB disk — ภาครัฐที่ลง plugin RBAC/Audit/Pipeline ควรเริ่ม 2 vCPU / 4 GB (JVM heap 2 GB) | AF6: ห้ามรัน Build บน Master (Controller) — ให้สั่ง Agent เท่านั้น เพื่อกัน Master ล่มและกันช่องโหว่ Script Approval
A7: jenkins-agent | B7: Jenkins Agent / Build Executor (ต่อ 1 Executor) | C7: 1 | D7: Pipeline Orchestration | E7: Core | F7: oss | G7: MIT | H7: 2 | I7: 4 | J7: 60 | K7: 4 | L7: 8 | M7: 200 | N7: 0 | O7: 0.3 | P7: resident | Q7: per_commit | R7: =INDEX('02_Freq_Weight'!$E$3:$E$9,MATCH(Q7,'02_Freq_Weight'!$A$3:$A$9,0)) | S7: 0.8 | T7: 7 | U7: 0.05 | V7: 0.2 | W7: pipeline, build, unit_test | X7: มาตรฐานข้อมูลเปิดภาครัฐ; พ.ร.บ. ปฏิบัติราชการทางอิเล็กทรอนิกส์ 2565 | Y7: CIS Benchmarks; ISO/IEC 25010:2023; ISO/IEC 27001:2022; ISO/IEC 27034; NIST SSDF (SP 800-218); OWASP Top 10:2025; SLSA v1.0 | Z7: - | AA7: C-SC-IMG, C-SC-PIN, C-SDLC-QUALITY, C-SDLC-TEST, C-SDLC-TRACE | AB7: 5 | AC7: CloudBees CI Agent; Azure Pipelines Agent | AE7: 1 Executor = 1 build พร้อมกัน; ประสบการณ์ทั่วไป 1 vCPU + 2 GB ต่อ executor เป็นขั้นต่ำ, 2 vCPU + 4 GB เมื่อ build Java/Node ที่มี dependency มาก | AF7: จำนวน Executor = จำนวน build ที่รันขนานได้ ให้คำนวณ vCPU/RAM แบบคูณจำนวน executor; Workspace ควรมี disk 60-200 GB และตั้ง cleanup ทุกรอบ
A8: argo-workflows | B8: Argo Workflows (CNCF Graduated) | C8: 1 | D8: Pipeline Orchestration | E8: Core | F8: oss | G8: Apache-2.0 | H8: 1 | I8: 2 | J8: 10 | K8: 2 | L8: 4 | M8: 40 | N8: 1 | O8: 1 | P8: resident | Q8: resident | R8: =INDEX('02_Freq_Weight'!$E$3:$E$9,MATCH(Q8,'02_Freq_Weight'!$A$3:$A$9,0)) | S8: 0.15 | T8: 90 | U8: 0.1 | V8: 0.2 | W8: pipeline, webhook, audit_trail | X8: พ.ร.บ. คอมพิวเตอร์ 2550/2560; พ.ร.บ. ไซเบอร์ 2562; มาตรฐานข้อมูลเปิดภาครัฐ; พ.ร.บ. ปฏิบัติราชการทางอิเล็กทรอนิกส์ 2565; ขมธอ. ลายมือชื่อ/เอกสารอิเล็กทรอนิกส์; ITA (ป.ป.ช.); มาตรฐานขั้นต่ำ 2566; กรอบมาตรฐานไซเบอร์ 2564; มาตรฐานเว็บไซต์ 2568; PDPA 2562 | Y8: ISO 22301:2019; ISO/IEC 27001:2022; ISO/IEC 27018; ISO/IEC 27701; ISO/IEC 42001:2023; NIST SP 800-53r5; NIST CSF 2.0; NIST SSDF (SP 800-218); SLSA v1.0; SOC 2 (TSC) | Z8: C-LOG-AUDIT | AA8: C-LOG-90, C-OPS-BCP, C-SDLC-TRACE, C-WEB-SELF | AB8: 5 | AC8: Azure DevOps; CloudBees CI; Harness | AE8: Argo Workflows controller ทั่วไปตั้ง request 100m CPU / 128Mi และ limit ~500m / 1Gi; ต้องมี Kubernetes อยู่แล้ว | AF8: เหมาะเมื่อมี Kubernetes แล้ว — เบากว่า Jenkins มาก แต่ต้องนับ resource ของ K8s control plane เพิ่ม
A9: opa-conftest | B9: Open Policy Agent / Conftest (Policy-as-Code Gate) | C9: 1 | D9: Branch Protection | E9: Optional | F9: oss | G9: Apache-2.0 | H9: 1 | I9: 1 | J9: 5 | K9: 1 | L9: 2 | M9: 10 | N9: 0 | O9: 0 | P9: ci_seq | Q9: per_pr | R9: =INDEX('02_Freq_Weight'!$E$3:$E$9,MATCH(Q9,'02_Freq_Weight'!$A$3:$A$9,0)) | S9: 0.01 | T9: 90 | U9: 0.05 | V9: 0.1 | W9: branch_protection, iac_scan, quality_gate | X9: มาตรฐานคลาวด์ 2567 | Y9: CIS Benchmarks; ISO/IEC 27001:2022; ISO/IEC 27034; ISO/IEC 42001:2023; NIST SSDF (SP 800-218); OWASP SAMM 2; OWASP Top 10:2025; SOC 2 (TSC) | Z9: C-OPS-IAC | AA9: C-AI-GOV, C-SDLC-REVIEW, C-SDLC-THREAT | AB9: 4 | AC9: GitHub Enterprise Branch Protection; GitLab Premium Protected Branches; Azure Branch Policies | AE9: OPA binary เดียว ใช้ RAM หลักสิบ MB ตอนประเมิน policy; ค่าขั้นต่ำ 1 vCPU / 1 GB คือการกันที่ให้ container | AF9: ใช้บังคับกฎ 'ต้องมี 2 Approvers' และตรวจ Terraform/K8s YAML ก่อน Merge ตาม CORE-R1
A10: nginx-gateway | B10: Nginx (Reverse Proxy / Webhook Relay) | C10: 1 | D10: Webhook Trigger | E10: Core | F10: oss | G10: BSD-2 | H10: 1 | I10: 1 | J10: 10 | K10: 2 | L10: 4 | M10: 40 | N10: 1 | O10: 0.3 | P10: resident | Q10: resident | R10: =INDEX('02_Freq_Weight'!$E$3:$E$9,MATCH(Q10,'02_Freq_Weight'!$A$3:$A$9,0)) | S10: 0.1 | T10: 90 | U10: 0.1 | V10: 0.2 | W10: webhook, tls_check | X10: มสพร. 11-2566 เว็บไซต์ภาครัฐ 3.0; มาตรฐานข้อมูลเปิดภาครัฐ; พ.ร.บ. ปฏิบัติราชการทางอิเล็กทรอนิกส์ 2565; ขมธอ. ความมั่นคงปลอดภัยสารสนเทศ; มาตรฐานเว็บไซต์ 2568; PDPA 2562; ประกาศ PDPC มาตรการความปลอดภัย 2565; พ.ร.ฎ. วิธีการแบบปลอดภัย 2553 | Y10: CycloneDX / ECMA-424; ISO/IEC 27018; ISO/IEC 27701; ISO/IEC 29100; NIST PQC Migration; NIST SSDF (SP 800-218); OWASP Top 10:2025; PCI DSS v4.0; SLSA v1.0 | Z10: C-CRY-TLS | AA10: C-CRY-PQC, C-PRV-MEASURE, C-SDLC-TRACE | AB10: 4 | AC10: F5 BIG-IP; Azure Application Gateway; AWS ALB | AE10: Nginx worker กิน RAM หลักสิบ MB ต่อ worker; 1 vCPU / 1 GB รองรับหลักพัน req/s ของ webhook ได้ | AF10: โดยทั่วไปวาง Reverse Proxy แยกเครื่อง (2 vCPU / 4 GB เพียงพอสำหรับ traffic ระดับหน่วยงาน); บนเครื่อง CI ใช้เพียง relay webhook ผ่าน Proxy Whitelist จึงกินทรัพยากรน้อยมาก
A11: sonarqube | B11: SonarQube Community Edition | C11: 2 | D11: SAST + Code Quality | E11: Core | F11: oss | G11: LGPL-3.0 | H11: 2 | I11: 4 | J11: 30 | K11: 4 | L11: 8 | M11: 100 | N11: 1 | O11: 3.5 | P11: resident | Q11: resident | R11: =INDEX('02_Freq_Weight'!$E$3:$E$9,MATCH(Q11,'02_Freq_Weight'!$A$3:$A$9,0)) | S11: 0.1 | T11: 365 | U11: 0.3 | V11: 0.2 | W11: sast, code_quality, quality_gate | X11: ขมธอ. ความมั่นคงปลอดภัยสารสนเทศ; มาตรฐานเว็บไซต์ 2568 | Y11: CIS Controls v8.1; ISO/IEC 25010:2023; ISO/IEC 27001:2022; ISO/IEC 27002:2022; ISO/IEC 27034; ISO/IEC 42001:2023; NIST SP 800-53r5; NIST SSDF (SP 800-218); OWASP API Top 10:2023; OWASP ASVS 5.0; OWASP MASVS; OWASP SAMM 2; OWASP Top 10:2025; PCI DSS v4.0; SOC 2 (TSC) | Z11: C-APP-ERROR, C-SDLC-SAST, C-SDLC-THREAT | AA11: C-AI-GOV, C-APP-ACCESS, C-APP-INJECT, C-SDLC-QUALITY, C-SDLC-REVIEW | AB11: 8 | AC11: SonarQube Enterprise; Checkmarx SAST; Fortify SCA; Veracode Static Analysis | AD11: Semgrep; SpotBugs; Bandit; gosec; Brakeman; ESLint Security | AE11: SonarQube docs: ขั้นต่ำ 2 GB RAM ว่างสำหรับ server + 1 GB สำหรับ OS; ตัว server รัน 3 process (Web + Compute Engine + Elasticsearch) จึงควรมี 4 GB ขึ้นไป และตั้ง vm.max_map_count=524288 | AF11: เป็นหัวใจของ Quality Gate; ต้องมี PostgreSQL แยก (ห้ามใช้ embedded H2 ใน production) และมี Embedded Elasticsearch อยู่ในตัว ทำให้ RAM เป็นค่าคงค้างตลอดเวลา ไม่ใช่ค่าชั่วคราว — เป็นเหตุผลหลักที่เครื่อง Orchestrator มักต้องการ RAM มากกว่าที่ประเมินไว้ตอนแรก
A12: postgresql-tools | B12: PostgreSQL (ฐานข้อมูลของเครื่องมือ CI/CD) | C12: 2 | D12: Supporting Database | E12: Core | F12: oss | G12: PostgreSQL License | H12: 2 | I12: 4 | J12: 20 | K12: 4 | L12: 8 | M12: 100 | N12: 1 | O12: 3 | P12: resident | Q12: resident | R12: =INDEX('02_Freq_Weight'!$E$3:$E$9,MATCH(Q12,'02_Freq_Weight'!$A$3:$A$9,0)) | S12: 0.05 | T12: 2555 | U12: 0.35 | V12: 0.2 | W12: audit_trail | X12: พ.ร.บ. คอมพิวเตอร์ 2550/2560; พ.ร.บ. ไซเบอร์ 2562; มาตรฐานข้อมูลเปิดภาครัฐ; พ.ร.บ. ปฏิบัติราชการทางอิเล็กทรอนิกส์ 2565; ขมธอ. ลายมือชื่อ/เอกสารอิเล็กทรอนิกส์; ITA (ป.ป.ช.); มาตรฐานขั้นต่ำ 2566; กรอบมาตรฐานไซเบอร์ 2564; มาตรฐานเว็บไซต์ 2568; PDPA 2562 | Y12: ISO 22301:2019; ISO/IEC 27001:2022; ISO/IEC 27018; ISO/IEC 27701; ISO/IEC 42001:2023; NIST SP 800-53r5; NIST CSF 2.0; NIST SSDF (SP 800-218); SLSA v1.0; SOC 2 (TSC) | Z12: C-LOG-AUDIT | AA12: C-LOG-90, C-OPS-BCP, C-SDLC-TRACE, C-WEB-SELF | AB12: 5 | AC12: Azure Database for PostgreSQL; AWS RDS; Oracle Database | AE12: PostgreSQL ทำงานได้ที่ 1 GB แต่ shared_buffers 25% ของ RAM + work_mem ต่อ connection ทำให้ 4 GB เป็นค่าที่ปลอดภัยเมื่อรองรับ SonarQube + Jenkins | AF12: SonarQube ต้องมี PostgreSQL แยก (ห้ามใช้ embedded H2 ใน production); ถ้าเก็บ Audit Trail 7 ปีตามภาครัฐ ต้องวางแผน partition + archive
A13: semgrep | B13: Semgrep (SAST แบบ Rule-based) | C13: 2 | D13: SAST | E13: Core | F13: oss | G13: LGPL-2.1 | H13: 2 | I13: 4 | J13: 5 | K13: 4 | L13: 8 | M13: 20 | N13: 0 | O13: 0 | P13: ci_seq | Q13: per_commit | R13: =INDEX('02_Freq_Weight'!$E$3:$E$9,MATCH(Q13,'02_Freq_Weight'!$A$3:$A$9,0)) | S13: 0.02 | T13: 180 | U13: 0.05 | V13: 0.15 | W13: sast | X13: ขมธอ. ความมั่นคงปลอดภัยสารสนเทศ; มาตรฐานเว็บไซต์ 2568 | Y13: CIS Controls v8.1; ISO/IEC 27002:2022; ISO/IEC 27034; NIST SP 800-53r5; NIST SSDF (SP 800-218); OWASP API Top 10:2023; OWASP ASVS 5.0; OWASP MASVS; OWASP SAMM 2; OWASP Top 10:2025; PCI DSS v4.0 | Z13: C-SDLC-SAST | AA13: C-APP-ACCESS, C-APP-ERROR, C-APP-INJECT | AB13: 4 | AC13: Semgrep Enterprise; Checkmarx SAST; Fortify SCA; CodeQL (GitHub Advanced Security) | AE13: Semgrep แนะนำ ~4 GB RAM สำหรับ repo ขนาดกลาง; RAM ขึ้นกับขนาดไฟล์ที่ใหญ่สุด ไม่ใช่จำนวนไฟล์ | AF13: เร็วกว่า SonarQube หลายเท่า เหมาะรันทุก commit เป็น Fast Gate แล้วปล่อย SonarQube รันรอบ nightly
A14: gitleaks | B14: GitLeaks / TruffleHog (Secret Scanning) | C14: 2 | D14: Secret Scanning | E14: Core | F14: oss | G14: MIT | H14: 1 | I14: 2 | J14: 3 | K14: 2 | L14: 4 | M14: 10 | N14: 0 | O14: 0 | P14: ci_seq | Q14: per_commit | R14: =INDEX('02_Freq_Weight'!$E$3:$E$9,MATCH(Q14,'02_Freq_Weight'!$A$3:$A$9,0)) | S14: 0.01 | T14: 365 | U14: 0.05 | V14: 0.1 | W14: secret_scan | X14: PDPA 2562 | Y14: ISO/IEC 27002:2022; ISO/IEC 27018; ISO/IEC 27701; ISO/IEC 29100 | Z14: - | AA14: C-PRV-MINIMIZE, C-SDLC-SECRET | AB14: 2 | AC14: GitHub Advanced Security Secret Scanning; GitLab Ultimate Secret Detection; HashiCorp Vault Radar | AE14: GitLeaks เป็น Go binary สแกน git history ด้วย regex/entropy; RAM ~200-500 MB ต่อ repo ขนาดกลาง | AF14: ต้องตั้งเป็น Blocking Gate (พบ = หยุด Pipeline) ตาม PDPA-R3; ควรติดตั้ง pre-commit hook ที่ฝั่ง Developer ด้วย
A15: dependency-check | B15: OWASP Dependency-Check (SCA) | C15: 2 | D15: Software Composition Analysis | E15: Optional | F15: oss | G15: Apache-2.0 | H15: 2 | I15: 4 | J15: 15 | K15: 4 | L15: 8 | M15: 40 | N15: 0 | O15: 0.5 | P15: async | Q15: nightly | R15: =INDEX('02_Freq_Weight'!$E$3:$E$9,MATCH(Q15,'02_Freq_Weight'!$A$3:$A$9,0)) | S15: 0.05 | T15: 365 | U15: 0.1 | V15: 0.15 | W15: sca, sbom | X15: มาตรฐานขั้นต่ำ 2566 | Y15: CIS Controls v8.1; CSA CCM v4 / STAR; CycloneDX / ECMA-424; ISO/IEC 27002:2022; NIST SP 800-161r1; NIST SSDF (SP 800-218); OWASP Top 10:2025; PCI DSS v4.0; SLSA v1.0; SPDX / ISO 5962 | Z15: C-SC-SBOM, C-SC-SCA | AA15: - | AB15: 2 | AC15: Snyk Enterprise; BlackDuck (Synopsys); JFrog Xray; Sonatype Nexus Lifecycle; Mend (WhiteSource) | AD15: Trivy; Grype (Anchore); Dependency-Track; OSV-Scanner | AE15: Dependency-Check ต้องดาวน์โหลดและ cache NVD CVE Database (~2-8 GB) และแนะนำ JVM heap 4 GB; รอบแรกใช้เวลา 20-60 นาที | AF15: ควรย้ายไปรันรอบ nightly เพราะช้า และตั้ง NVD_API_KEY + local mirror เพื่อรองรับ Air-gapped ตามภาครัฐ
A16: trivy | B16: Trivy (SCA + Container + IaC + Secret ในตัวเดียว) | C16: 2 | D16: Multi-purpose Scanner | E16: Core | F16: oss | G16: Apache-2.0 | H16: 2 | I16: 2 | J16: 10 | K16: 2 | L16: 4 | M16: 30 | N16: 0 | O16: 0 | P16: ci_seq | Q16: per_build | R16: =INDEX('02_Freq_Weight'!$E$3:$E$9,MATCH(Q16,'02_Freq_Weight'!$A$3:$A$9,0)) | S16: 0.03 | T16: 365 | U16: 0.05 | V16: 0.15 | W16: sca, container_scan, iac_scan, secret_scan, sbom | X16: มาตรฐานคลาวด์ 2567; มาตรฐานขั้นต่ำ 2566; PDPA 2562 | Y16: CIS Benchmarks; CIS Controls v8.1; CSA CCM v4 / STAR; CycloneDX / ECMA-424; ISO/IEC 27002:2022; ISO/IEC 27018; ISO/IEC 27701; ISO/IEC 29100; NIST SP 800-161r1; NIST SSDF (SP 800-218); OWASP Top 10:2025; PCI DSS v4.0; SLSA v1.0; SPDX / ISO 5962 | Z16: C-OPS-IAC, C-SC-CONTAINER, C-SC-SBOM, C-SC-SCA | AA16: C-PRV-MINIMIZE, C-SDLC-SECRET | AB16: 6 | AC16: Aqua Container Security; Prisma Cloud (Twistlock); Snyk Container; JFrog Xray | AE16: Trivy เป็น Go binary; vulnerability DB cache ~1-3 GB, Java DB เพิ่มอีก ~1-2 GB; RAM ปกติ < 1 GB แต่ image ใหญ่อาจถึง 2 GB | AF16: คุ้มค่าที่สุดต่อ resource เพราะทำได้ 5 หน้าที่ในตัวเดียว ลดจำนวนเครื่องมือที่ต้องแชร์เครื่อง — แนะนำเป็นตัวหลักเมื่อ VM จำกัด
A17: fossology | B17: FOSSology / ScanCode (License Compliance) | C17: 2 | D17: License Compliance | E17: Optional | F17: oss | G17: GPL-2.0 | H17: 4 | I17: 8 | J17: 30 | K17: 4 | L17: 8 | M17: 100 | N17: 1 | O17: 2 | P17: resident | Q17: weekly | R17: =INDEX('02_Freq_Weight'!$E$3:$E$9,MATCH(Q17,'02_Freq_Weight'!$A$3:$A$9,0)) | S17: 0.05 | T17: 730 | U17: 0.2 | V17: 0.1 | W17: license | X17: - | Y17: ISO/IEC 27001:2022; NIST SP 800-161r1; SPDX / ISO 5962 | Z17: C-SC-LICENSE | AA17: - | AB17: 1 | AC17: BlackDuck License Compliance; FOSSA Enterprise; Mend (WhiteSource); Snyk License | AD17: ScanCode Toolkit; License Finder; Licensee; REUSE | AE17: FOSSology เป็น web app + PostgreSQL + scheduler; เอกสารแนะนำ 4 GB RAM ขึ้นไป และ CPU มากขึ้นตามจำนวน agent ที่รันขนาน | AF17: ภาครัฐบังคับ 'ห้ามใช้ GPL/AGPL' — ควรรัน ScanCode Toolkit (เบากว่า, ephemeral) ทุก build และเก็บ FOSSology ไว้ทำ audit รายสัปดาห์แทน
A18: linters | B18: Linters (ESLint / Pylint / golangci-lint / RuboCop) | C18: 2 | D18: Code Quality | E18: Optional | F18: oss | G18: MIT | H18: 1 | I18: 2 | J18: 3 | K18: 2 | L18: 4 | M18: 10 | N18: 0 | O18: 0 | P18: ci_seq | Q18: per_commit | R18: =INDEX('02_Freq_Weight'!$E$3:$E$9,MATCH(Q18,'02_Freq_Weight'!$A$3:$A$9,0)) | S18: 0.01 | T18: 90 | U18: 0.05 | V18: 0.1 | W18: code_quality | X18: - | Y18: ISO/IEC 25010:2023; ISO/IEC 27001:2022; ISO/IEC 27034; OWASP ASVS 5.0; OWASP MASVS; OWASP SAMM 2; OWASP Top 10:2025 | Z18: - | AA18: C-APP-ERROR, C-SDLC-QUALITY, C-SDLC-THREAT | AB18: 3 | AC18: SonarQube Enterprise; CodeClimate Enterprise; Codacy Enterprise | AE18: Linter ทำงานใน process เดียว ใช้ RAM 200 MB - 1 GB ตามขนาด codebase; golangci-lint อาจถึง 2 GB บน monorepo | AF18: ควรรันบน Runner ของผู้ให้บริการ Git ก่อนส่ง Webhook เข้า Orchestrator ในองค์กร เพื่อไม่กินทรัพยากร VM ที่หน่วยงานต้องจัดหาเอง
A19: maven-gradle | B19: Maven / Gradle / npm / pip (Build & Compilation) | C19: 3 | D19: Build & Compilation | E19: Core | F19: oss | G19: Apache-2.0 | H19: 2 | I19: 4 | J19: 40 | K19: 4 | L19: 8 | M19: 120 | N19: 0 | O19: 0 | P19: ci_seq | Q19: per_commit | R19: =INDEX('02_Freq_Weight'!$E$3:$E$9,MATCH(Q19,'02_Freq_Weight'!$A$3:$A$9,0)) | S19: 0.3 | T19: 30 | U19: 0.05 | V19: 0.2 | W19: build | X19: - | Y19: CIS Benchmarks; NIST SSDF (SP 800-218); OWASP Top 10:2025; SLSA v1.0 | Z19: - | AA19: C-SC-IMG, C-SC-PIN | AB19: 2 | AC19: JFrog Artifactory (with Maven/Gradle); Azure DevOps Build; AWS CodeBuild; CloudBees Build | AE19: Gradle daemon ตั้ง heap 1-2 GB โดยปริยาย; Maven fork JVM ต่อ module; local cache ~/.m2 หรือ ~/.gradle โต 5-20 GB และ node_modules 1-3 GB ต่อโปรเจกต์ | AF19: อย่าลืมกัน disk ให้ dependency cache — เป็นสาเหตุ 'disk full' อันดับ 1 บนเครื่อง Agent; ควรตั้ง cache cleanup รายสัปดาห์
A20: docker-buildkit | B20: Docker Engine / BuildKit (Container Image Builder) | C20: 3 | D20: Container Image Builder | E20: Core | F20: oss | G20: Apache-2.0 | H20: 2 | I20: 4 | J20: 100 | K20: 4 | L20: 8 | M20: 300 | N20: 1 | O20: 0.5 | P20: ci_seq | Q20: per_commit | R20: =INDEX('02_Freq_Weight'!$E$3:$E$9,MATCH(Q20,'02_Freq_Weight'!$A$3:$A$9,0)) | S20: 2 | T20: 21 | U20: 0.1 | V20: 0.2 | W20: image_build, build | X20: - | Y20: CIS Benchmarks; NIST SSDF (SP 800-218); OWASP Top 10:2025; SLSA v1.0 | Z20: C-SC-IMG | AA20: C-SC-PIN | AB20: 2 | AC20: Google Cloud Build; Azure Container Registry Build; Red Hat Quay Build; AWS CodeBuild | AD20: Kaniko; Buildah; Podman; Cloud Native Buildpacks; img; ko | AE20: Docker daemon idle ~200-400 MB; multi-stage build ของ Java/Node ใช้ 2-4 GB ตอน compile layer; image layer cache เป็นตัวกิน disk หลัก | AF20: จุดเสี่ยงหลักคือ Disk ไม่ใช่ RAM — layer cache + dangling image โต 2-5 GB/วัน ต้องตั้ง `docker system prune` เป็น cron; ถ้าต้องการ Rootless Build ตามข้อกำหนดภาครัฐให้ใช้ Kaniko/Buildah แทน
A21: checkov | B21: Checkov / tfsec / KubeLinter (IaC Validation) | C21: 3 | D21: IaC Validation | E21: Optional | F21: oss | G21: Apache-2.0 | H21: 1 | I21: 2 | J21: 5 | K21: 2 | L21: 4 | M21: 15 | N21: 0 | O21: 0 | P21: ci_seq | Q21: per_build | R21: =INDEX('02_Freq_Weight'!$E$3:$E$9,MATCH(Q21,'02_Freq_Weight'!$A$3:$A$9,0)) | S21: 0.01 | T21: 365 | U21: 0.05 | V21: 0.1 | W21: iac_scan | X21: มาตรฐานคลาวด์ 2567 | Y21: CIS Benchmarks; OWASP Top 10:2025 | Z21: C-OPS-IAC | AA21: - | AB21: 1 | AC21: Prisma Cloud IaC Scanning; Snyk IaC Enterprise; Bridgecrew | AE21: Checkov เป็น Python CLI ใช้ RAM 300 MB - 1.5 GB ตามจำนวนไฟล์ Terraform/K8s; ephemeral ทั้งหมด | AF21: ภาครัฐกำหนดเป็น Mandatory (ตาม OWASP A02 + CLOUD2567-R1) — ตรวจ Security Group เปิดกว้าง, ไม่มี Resource Limits, ไม่ได้เข้ารหัส Volume
A22: cosign | B22: Sigstore Cosign / Notary v2 (Artifact Signing) | C22: 3 | D22: Artifact Signing | E22: Optional | F22: oss | G22: Apache-2.0 | H22: 1 | I22: 2 | J22: 5 | K22: 1 | L22: 2 | M22: 10 | N22: 0 | O22: 0 | P22: ci_seq | Q22: per_build | R22: =INDEX('02_Freq_Weight'!$E$3:$E$9,MATCH(Q22,'02_Freq_Weight'!$A$3:$A$9,0)) | S22: 0.01 | T22: 2555 | U22: 0.05 | V22: 0.1 | W22: artifact_sign | X22: ขมธอ. ลายมือชื่อ/เอกสารอิเล็กทรอนิกส์ | Y22: ISO/IEC 42001:2023; NIST SP 800-161r1; NIST SSDF (SP 800-218); OWASP Top 10:2025; SLSA v1.0 | Z22: C-SC-SIGN | AA22: C-AI-GOV | AB22: 2 | AC22: Azure Code Signing; AWS Signer; Venafi CodeSign Protect; Google Binary Authorization | AE22: Cosign เป็น Go binary ใช้ RAM < 300 MB; ต้องมีที่เก็บ key อย่างปลอดภัย (KMS/Vault) และ Rekor transparency log ถ้าต้องการ | AF22: ภาครัฐกำหนด Mandatory ตาม OWASP A08 + NIST SSDF — ต้อง Verify signature ก่อน Pull มา Deploy ทุกครั้ง ไม่ใช่แค่ Sign
A23: syft | B23: Syft / CycloneDX CLI (SBOM Generation) | C23: 3 | D23: SBOM | E23: Optional | F23: oss | G23: Apache-2.0 | H23: 1 | I23: 2 | J23: 5 | K23: 2 | L23: 4 | M23: 20 | N23: 0 | O23: 0 | P23: ci_seq | Q23: per_build | R23: =INDEX('02_Freq_Weight'!$E$3:$E$9,MATCH(Q23,'02_Freq_Weight'!$A$3:$A$9,0)) | S23: 0.02 | T23: 2555 | U23: 0.05 | V23: 0.15 | W23: sbom | X23: มาตรฐานขั้นต่ำ 2566 | Y23: CSA CCM v4 / STAR; CycloneDX / ECMA-424; NIST SP 800-161r1; NIST SSDF (SP 800-218); OWASP Top 10:2025; SLSA v1.0; SPDX / ISO 5962 | Z23: C-SC-SBOM | AA23: - | AB23: 1 | AC23: JFrog Xray SBOM; Snyk SBOM; BlackDuck SBOM; Google Cloud SBOM | AE23: Syft สแกน image layer สร้าง SBOM; RAM ~500 MB - 2 GB ตามขนาด image; ไฟล์ SBOM 1-10 MB ต่อ artifact | AF23: ภาครัฐกำหนด Mandatory ตาม OWASP A03 + NIST SP 800-161; SBOM ต้องเก็บคู่กับ artifact และเก็บนานเท่ากับอายุการใช้งานระบบ (7+ ปี)
A24: unit-test-runner | B24: pytest / Jest / JUnit / Go test (Unit Test) | C24: 4 | D24: Unit Test | E24: Core | F24: oss | G24: MIT | H24: 2 | I24: 4 | J24: 20 | K24: 4 | L24: 8 | M24: 60 | N24: 0 | O24: 0 | P24: ci_seq | Q24: per_commit | R24: =INDEX('02_Freq_Weight'!$E$3:$E$9,MATCH(Q24,'02_Freq_Weight'!$A$3:$A$9,0)) | S24: 0.1 | T24: 90 | U24: 0.05 | V24: 0.15 | W24: unit_test, code_quality | X24: - | Y24: ISO/IEC 25010:2023; ISO/IEC 27001:2022; ISO/IEC 27034; NIST SSDF (SP 800-218); OWASP ASVS 5.0; OWASP MASVS; OWASP SAMM 2; OWASP Top 10:2025 | Z24: C-SDLC-QUALITY | AA24: C-APP-ERROR, C-SDLC-TEST, C-SDLC-THREAT | AB24: 4 | AC24: Visual Studio Test Professional; TestNG Enterprise; NCrunch; JUnit (IntelliJ Ultimate) | AE24: Test runner แบบขนาน (pytest-xdist / Jest workers) ใช้ RAM ≈ 500 MB ต่อ worker; 4 worker ≈ 2-4 GB | AF24: ภาครัฐบังคับ Coverage > 80% — coverage instrumentation ทำให้ใช้ RAM และเวลาเพิ่ม ~30-50% ต้องเผื่อไว้
A25: testcontainers | B25: Testcontainers / WireMock / Pact (Integration Test) | C25: 4 | D25: Integration Test | E25: Core | F25: oss | G25: MIT | H25: 4 | I25: 8 | J25: 40 | K25: 4 | L25: 8 | M25: 100 | N25: 0 | O25: 0 | P25: ci_seq | Q25: per_build | R25: =INDEX('02_Freq_Weight'!$E$3:$E$9,MATCH(Q25,'02_Freq_Weight'!$A$3:$A$9,0)) | S25: 0.15 | T25: 90 | U25: 0.05 | V25: 0.15 | W25: integration_test | X25: - | Y25: ISO/IEC 25010:2023; ISO/IEC 27001:2022; ISO/IEC 27034; NIST SSDF (SP 800-218) | Z25: - | AA25: C-SDLC-TEST | AB25: 1 | AC25: Tricentis Tosca; SmartBear ReadyAPI; Parasoft SOAtest; Postman Enterprise | AE25: Integration test ที่ spin ฐานข้อมูล/queue จริงเป็น container ต้องบวก RAM ของ PostgreSQL (~1 GB) + Redis (~0.5 GB) + RabbitMQ (~1 GB) เข้าไปในตอนรัน | AF25: เป็นขั้นที่กิน RAM สูงสุดใน Stage 4 เพราะรัน dependency จริงพร้อมกัน — อย่าให้ทับเวลากับ DAST Full Scan
A26: owasp-zap | B26: OWASP ZAP (DAST + API Security) | C26: 4 | D26: DAST | E26: Optional | F26: oss | G26: Apache-2.0 | H26: 2 | I26: 4 | J26: 20 | K26: 4 | L26: 8 | M26: 60 | N26: 0 | O26: 0 | P26: async | Q26: nightly | R26: =INDEX('02_Freq_Weight'!$E$3:$E$9,MATCH(Q26,'02_Freq_Weight'!$A$3:$A$9,0)) | S26: 0.15 | T26: 730 | U26: 0.1 | V26: 0.15 | W26: dast, api_security, vapt | X26: พ.ร.บ. ไซเบอร์ 2562; ITA (ป.ป.ช.); มาตรฐานขั้นต่ำ 2566; กรอบมาตรฐานไซเบอร์ 2564; มาตรฐานเว็บไซต์ 2568 | Y26: CIS Controls v8.1; ISO/IEC 27001:2022; ISO/IEC 27034; NIST SP 800-53r5; NIST SP 800-63B; OWASP API Top 10:2023; OWASP ASVS 5.0; OWASP MASVS; OWASP SAMM 2; OWASP Top 10:2025; PCI DSS v4.0 | Z26: C-APP-API, C-APP-DAST, C-APP-PENTEST | AA26: C-APP-ACCESS, C-APP-AUTHN, C-APP-INJECT, C-WEB-SELF | AB26: 7 | AC26: Veracode Dynamic Analysis; Burp Suite Professional; Acunetix; Rapid7 InsightAppSec; StackHawk | AD26: Nikto; w3af; Nuclei; Arachni; RESTler; Schemathesis | AE26: ZAP เป็น Java app ค่าปริยาย heap ~25% ของ RAM เครื่อง; Full Scan/AJAX Spider บนเว็บใหญ่ควรตั้ง -Xmx 4 GB ขึ้นไป และ session file โต 1-10 GB ต่อรอบ | AF26: แนวปฏิบัติที่ดีคือติดตั้ง ZAP บนเครื่องหนึ่งแล้วยิงสแกนข้ามเครื่องไปยัง Target ที่รันอยู่ (ห้ามยิงตัวเองเพราะจะแย่ง CPU กันจนผลเพี้ยน); การติดตั้งแบบ Native บน Host แทนการรันใน Docker ช่วยลด RAM ได้ประมาณ 15-20% เมื่อทรัพยากรจำกัด
A27: nuclei | B27: Nuclei (Template-based Vulnerability Scan) | C27: 4 | D27: DAST | E27: Optional | F27: oss | G27: MIT | H27: 2 | I27: 2 | J27: 10 | K27: 2 | L27: 4 | M27: 20 | N27: 0 | O27: 0 | P27: async | Q27: nightly | R27: =INDEX('02_Freq_Weight'!$E$3:$E$9,MATCH(Q27,'02_Freq_Weight'!$A$3:$A$9,0)) | S27: 0.05 | T27: 365 | U27: 0.05 | V27: 0.15 | W27: dast, api_security, vapt, tls_check | X27: พ.ร.บ. ไซเบอร์ 2562; มสพร. 11-2566 เว็บไซต์ภาครัฐ 3.0; พ.ร.บ. ปฏิบัติราชการทางอิเล็กทรอนิกส์ 2565; ขมธอ. ความมั่นคงปลอดภัยสารสนเทศ; ITA (ป.ป.ช.); มาตรฐานขั้นต่ำ 2566; กรอบมาตรฐานไซเบอร์ 2564; มาตรฐานเว็บไซต์ 2568; PDPA 2562; ประกาศ PDPC มาตรการความปลอดภัย 2565; พ.ร.ฎ. วิธีการแบบปลอดภัย 2553 | Y27: CIS Controls v8.1; CycloneDX / ECMA-424; ISO/IEC 27001:2022; ISO/IEC 27018; ISO/IEC 27034; ISO/IEC 27701; ISO/IEC 29100; NIST SP 800-53r5; NIST SP 800-63B; NIST PQC Migration; OWASP API Top 10:2023; OWASP ASVS 5.0; OWASP MASVS; OWASP SAMM 2; OWASP Top 10:2025; PCI DSS v4.0 | Z27: C-APP-API, C-APP-DAST, C-APP-PENTEST, C-CRY-TLS | AA27: C-APP-ACCESS, C-APP-AUTHN, C-APP-INJECT, C-CRY-PQC, C-PRV-MEASURE, C-WEB-SELF | AB27: 10 | AC27: Rapid7 InsightAppSec; Tenable.io; Qualys WAS | AE27: Nuclei เป็น Go binary รัน template ขนานสูง; RAM 500 MB - 2 GB ตามจำนวน concurrency ที่ตั้ง | AF27: เบากว่า ZAP มาก เหมาะรันทุกวันเป็น Fast Security Gate แล้วปล่อย ZAP Full Scan รอบสัปดาห์
A28: locust | B28: Locust (Performance / Load Test) | C28: 4 | D28: Performance Test | E28: Optional | F28: oss | G28: MIT | H28: 4 | I28: 8 | J28: 20 | K28: 8 | L28: 16 | M28: 60 | N28: 0 | O28: 0 | P28: load | Q28: weekly | R28: =INDEX('02_Freq_Weight'!$E$3:$E$9,MATCH(Q28,'02_Freq_Weight'!$A$3:$A$9,0)) | S28: 0.05 | T28: 365 | U28: 0.1 | V28: 0.15 | W28: perf_test | X28: - | Y28: ISO/IEC 25010:2023; ISO/IEC 27001:2022 | Z28: C-OPS-PERF | AA28: - | AB28: 1 | AC28: BlazeMeter; LoadRunner Enterprise; NeoLoad; Gatling Enterprise | AD28: K6; Apache JMeter; Gatling; Artillery; Vegeta; wrk | AE28: Locust ใช้ ~1 CPU core ต่อ ~1,000 concurrent users (แบบ single-process) จึงต้องรัน master + workers; แนะนำ 1 worker ต่อ core และ RAM ~1 GB ต่อ 1,000 users | AF28: ข้อควรระวังสำคัญ: ถ้ารัน Load Generator บนเครื่องเดียวกับระบบที่กำลังทดสอบ ผลการวัดจะเพี้ยน เพราะแย่ง CPU กันเอง ควรแยกเครื่องหรือแยกช่วงเวลาให้ชัดเจน และต้องกันทรัพยากรไว้เต็มจำนวนในช่วงที่รัน
A29: playwright-a11y | B29: Playwright + axe-core / pa11y-ci / Lighthouse CI (Accessibility) | C29: 4 | D29: Accessibility Test | E29: Optional | F29: oss | G29: Apache-2.0 | H29: 2 | I29: 4 | J29: 15 | K29: 4 | L29: 8 | M29: 40 | N29: 0 | O29: 0 | P29: async | Q29: nightly | R29: =INDEX('02_Freq_Weight'!$E$3:$E$9,MATCH(Q29,'02_Freq_Weight'!$A$3:$A$9,0)) | S29: 0.05 | T29: 365 | U29: 0.05 | V29: 0.1 | W29: accessibility, integration_test | X29: มสพร. 11-2566 เว็บไซต์ภาครัฐ 3.0 | Y29: ISO/IEC 25010:2023; ISO/IEC 27001:2022; ISO/IEC 27034; NIST SSDF (SP 800-218); WCAG 2.2 AA | Z29: C-WEB-A11Y | AA29: C-SDLC-TEST | AB29: 2 | AC29: Deque axe DevTools Pro; Siteimprove; Level Access | AE29: Headless Chromium ใช้ RAM ~300-700 MB ต่อ browser context; 4 context ขนาน ≈ 2-3 GB | AF29: จำเป็นสำหรับ .go.th ตาม มสพร. 11-2566 (WCAG 2.1/2.2 AA) — เป็นข้อที่โครงการภาครัฐมักตกเพราะไม่มีใน Pipeline; ต้องเก็บผลเป็นหลักฐาน Self-Assessment ตาม WEB2568-R4
A30: testssl | B30: testssl.sh / sslyze / CBOMkit (TLS + Crypto Inventory) | C30: 4 | D30: TLS & Crypto Validation | E30: Optional | F30: oss | G30: GPL-2.0 | H30: 1 | I30: 2 | J30: 5 | K30: 2 | L30: 2 | M30: 10 | N30: 0 | O30: 0 | P30: async | Q30: weekly | R30: =INDEX('02_Freq_Weight'!$E$3:$E$9,MATCH(Q30,'02_Freq_Weight'!$A$3:$A$9,0)) | S30: 0.01 | T30: 365 | U30: 0.05 | V30: 0.1 | W30: tls_check, crypto_agility | X30: มสพร. 11-2566 เว็บไซต์ภาครัฐ 3.0; พ.ร.บ. ปฏิบัติราชการทางอิเล็กทรอนิกส์ 2565; ขมธอ. ความมั่นคงปลอดภัยสารสนเทศ; มาตรฐานเว็บไซต์ 2568; PDPA 2562; ประกาศ PDPC มาตรการความปลอดภัย 2565; พ.ร.ฎ. วิธีการแบบปลอดภัย 2553 | Y30: CycloneDX / ECMA-424; ISO/IEC 27018; ISO/IEC 27701; ISO/IEC 29100; NIST PQC Migration; OWASP Top 10:2025; PCI DSS v4.0 | Z30: C-CRY-PQC, C-CRY-TLS | AA30: C-PRV-MEASURE | AB30: 3 | AC30: Qualys SSL Labs API; Venafi TLS Protect; Entrust | AE30: testssl.sh เป็น bash + openssl ใช้ RAM < 300 MB; ใช้เวลา 2-10 นาทีต่อ endpoint | AF30: ตรวจว่า TLS 1.2/1.3 เท่านั้น ไม่มี Self-signed ตาม มสพร. 11-2566 และ WEB2568-R1; CBOMkit ใช้ทำ Crypto Bill of Materials เตรียม Post-Quantum ตาม OWASP-PQC
A31: harbor | B31: Harbor (Private Container Registry, CNCF Graduated) | C31: 5 | D31: Container Registry | E31: Core | F31: oss | G31: Apache-2.0 | H31: 2 | I31: 4 | J31: 60 | K31: 4 | L31: 8 | M31: 200 | N31: 1 | O31: 3 | P31: resident | Q31: resident | R31: =INDEX('02_Freq_Weight'!$E$3:$E$9,MATCH(Q31,'02_Freq_Weight'!$A$3:$A$9,0)) | S31: 1 | T31: 180 | U31: 0.2 | V31: 0.25 | W31: registry, container_scan, artifact_sign, audit_trail, version_tag | X31: พ.ร.บ. คอมพิวเตอร์ 2550/2560; พ.ร.บ. ไซเบอร์ 2562; มาตรฐานข้อมูลเปิดภาครัฐ; พ.ร.บ. ปฏิบัติราชการทางอิเล็กทรอนิกส์ 2565; ขมธอ. ลายมือชื่อ/เอกสารอิเล็กทรอนิกส์; ITA (ป.ป.ช.); มาตรฐานขั้นต่ำ 2566; กรอบมาตรฐานไซเบอร์ 2564; มาตรฐานเว็บไซต์ 2568; PDPA 2562 | Y31: CIS Benchmarks; ISO 22301:2019; ISO/IEC 27001:2022; ISO/IEC 27018; ISO/IEC 27701; ISO/IEC 42001:2023; NIST SP 800-161r1; NIST SP 800-53r5; NIST CSF 2.0; NIST SSDF (SP 800-218); OWASP Top 10:2025; PCI DSS v4.0; SLSA v1.0; SOC 2 (TSC) | Z31: C-LOG-AUDIT, C-SC-CONTAINER, C-SC-REGISTRY, C-SC-SIGN | AA31: C-AI-GOV, C-LOG-90, C-OPS-BCP, C-SC-PIN, C-SDLC-TRACE, C-WEB-SELF | AB31: 10 | AC31: JFrog Artifactory Enterprise; Amazon ECR; Azure Container Registry; Google Artifact Registry | AD31: Zot; Quay.io; Distribution (Docker Registry); GitLab Container Registry | AE31: Harbor docs: minimum 2 CPU / 4 GB RAM / 40 GB disk; recommended 4 CPU / 8 GB RAM / 160 GB disk — ประกอบด้วย core, registry, jobservice, PostgreSQL, Redis, Trivy | AF31: รองรับ Air-gapped ตามข้อกำหนดภาครัฐ + มี Vulnerability Scan และ Cosign verification ในตัว; ต้องตั้ง Retention Policy ไม่งั้น disk โตไม่หยุด (2-5 GB/วัน จาก image tag ใหม่)
A32: minio | B32: MinIO (S3-compatible Object Storage) | C32: 5 | D32: Artifact Storage | E32: Core | F32: oss | G32: AGPL-3.0 | H32: 2 | I32: 4 | J32: 20 | K32: 4 | L32: 8 | M32: 500 | N32: 1 | O32: 1.5 | P32: resident | Q32: resident | R32: =INDEX('02_Freq_Weight'!$E$3:$E$9,MATCH(Q32,'02_Freq_Weight'!$A$3:$A$9,0)) | S32: 1 | T32: 180 | U32: 0.15 | V32: 0.25 | W32: registry, backup_dr, audit_trail | X32: พ.ร.บ. คอมพิวเตอร์ 2550/2560; พ.ร.บ. ไซเบอร์ 2562; มสพร. 11-2566 เว็บไซต์ภาครัฐ 3.0; มาตรฐานข้อมูลเปิดภาครัฐ; พ.ร.บ. ปฏิบัติราชการทางอิเล็กทรอนิกส์ 2565; ขมธอ. การใช้บริการคลาวด์; ขมธอ. ลายมือชื่อ/เอกสารอิเล็กทรอนิกส์; ITA (ป.ป.ช.); มาตรฐานขั้นต่ำ 2566; กรอบมาตรฐานไซเบอร์ 2564; มาตรฐานเว็บไซต์ 2568; PDPA 2562; พ.ร.ฎ. วิธีการแบบปลอดภัย 2553 | Y32: CIS Controls v8.1; ISO 22301:2019; ISO/IEC 27001:2022; ISO/IEC 27018; ISO/IEC 27701; ISO/IEC 42001:2023; NIST SP 800-161r1; NIST SP 800-53r5; NIST CSF 2.0; NIST SSDF (SP 800-218); OWASP Top 10:2025; SLSA v1.0; SOC 2 (TSC) | Z32: C-LOG-AUDIT, C-OPS-BACKUP, C-OPS-BCP, C-SC-REGISTRY | AA32: C-AI-GOV, C-LOG-90, C-SDLC-TRACE, C-WEB-SELF | AB32: 8 | AC32: Amazon S3; Azure Blob Storage; NetApp StorageGRID; Dell ECS | AE32: MinIO ขั้นต่ำใช้งานได้ที่ 2 vCPU / 4 GB (เอกสารแนะนำ 32 GB สำหรับ production ที่โหลดสูง เพราะ cache metadata ใน RAM); erasure coding ต้องมี 4 drive ขึ้นไปถ้าต้องการ HA | AF32: ใช้เป็นคลังเก็บ Container Image, Source Archive และ Report ที่เข้าถึงแบบ S3 API ได้ ต้องแยก Data Disk ออกจาก OS Disk เสมอ — ข้อควรระวัง License เป็น AGPL-3.0 ซึ่งขัดกับข้อห้าม ใช้ GPL/AGPL ของโครงการภาครัฐบางแห่ง ต้องตรวจว่าเข้าเงื่อนไข 'ไม่แก้ไข source และไม่ให้บริการต่อสาธารณะ' หรือขอ Commercial License
A33: elasticsearch | B33: Elasticsearch (Log / Audit Trail Index) | C33: 5 | D33: Log & Audit Store | E33: Core | F33: oss | G33: SSPL / Elastic License | H33: 2 | I33: 4 | J33: 40 | K33: 8 | L33: 16 | M33: 500 | N33: 1 | O33: 3.5 | P33: resident | Q33: resident | R33: =INDEX('02_Freq_Weight'!$E$3:$E$9,MATCH(Q33,'02_Freq_Weight'!$A$3:$A$9,0)) | S33: 1.5 | T33: 90 | U33: 0.45 | V33: 0.3 | W33: log_mgmt, audit_trail, siem_alert | X33: พ.ร.บ. คอมพิวเตอร์ 2550/2560; พ.ร.บ. ไซเบอร์ 2562; มสพร. 11-2566 เว็บไซต์ภาครัฐ 3.0; มาตรฐานข้อมูลเปิดภาครัฐ; พ.ร.บ. ปฏิบัติราชการทางอิเล็กทรอนิกส์ 2565; ขมธอ. ลายมือชื่อ/เอกสารอิเล็กทรอนิกส์; ขมธอ. ความมั่นคงปลอดภัยสารสนเทศ; ITA (ป.ป.ช.); มาตรฐานคลาวด์ 2567; มาตรฐานขั้นต่ำ 2566; กรอบมาตรฐานไซเบอร์ 2564; มาตรฐานเว็บไซต์ 2568; PDPA 2562; ประกาศ PDPC แจ้งเหตุละเมิด 2565; ประกาศ PDPC มาตรการความปลอดภัย 2565; พ.ร.ฎ. วิธีการแบบปลอดภัย 2553 | Y33: CIS Controls v8.1; CSA CCM v4 / STAR; ISO 22301:2019; ISO/IEC 27001:2022; ISO/IEC 27002:2022; ISO/IEC 27017; ISO/IEC 27018; ISO/IEC 27701; ISO/IEC 29100; ISO/IEC 42001:2023; NIST SP 800-207; NIST SP 800-53r5; NIST CSF 2.0; NIST SSDF (SP 800-218); OWASP ASVS 5.0; OWASP Top 10:2025; PCI DSS v4.0; SLSA v1.0; SOC 2 (TSC) | Z33: C-LOG-90, C-LOG-AUDIT, C-LOG-CENTRAL | AA33: C-LOG-NOTIFY, C-LOG-SIEM, C-OPS-BCP, C-PRV-BREACH, C-PRV-MEASURE, C-PRV-MINIMIZE, C-SDLC-TRACE, C-WEB-SELF | AB33: 11 | AC33: Splunk Enterprise; Datadog; Sumo Logic; Microsoft Sentinel | AE33: Elasticsearch แนะนำ JVM heap ไม่เกิน 50% ของ RAM และไม่เกิน ~31 GB; ที่ 4 GB RAM ต้องตั้ง ES_JAVA_OPTS=-Xms2g -Xmx2g; index overhead รวม replica + doc_values ประมาณ 30-50% ของ raw log | AF33: เป็นตัวกิน RAM และ Disk มากที่สุดในระบบ CI/CD — ถ้าต้องแชร์เครื่องกับ Orchestrator หรือ SAST ให้จำกัด heap ด้วย ES_JAVA_OPTS (เช่น 2-4 GB) เพื่อรักษาเสถียรภาพของเครื่อง; มาตรฐานขั้นต่ำ พ.ศ. 2566 บังคับเก็บ Log อย่างน้อย 90 วัน ซึ่งเป็นตัวกำหนดขนาด Data Disk โดยตรง
A34: logstash | B34: Logstash (Log Pipeline / Parser) | C34: 5 | D34: Log Ingest | E34: Optional | F34: oss | G34: SSPL / Elastic License | H34: 2 | I34: 4 | J34: 15 | K34: 2 | L34: 4 | M34: 40 | N34: 1 | O34: 1.5 | P34: resident | Q34: resident | R34: =INDEX('02_Freq_Weight'!$E$3:$E$9,MATCH(Q34,'02_Freq_Weight'!$A$3:$A$9,0)) | S34: 0.1 | T34: 30 | U34: 0.05 | V34: 0.2 | W34: log_mgmt | X34: พ.ร.บ. คอมพิวเตอร์ 2550/2560; มสพร. 11-2566 เว็บไซต์ภาครัฐ 3.0; ขมธอ. ความมั่นคงปลอดภัยสารสนเทศ; มาตรฐานคลาวด์ 2567; มาตรฐานขั้นต่ำ 2566; มาตรฐานเว็บไซต์ 2568; PDPA 2562; ประกาศ PDPC แจ้งเหตุละเมิด 2565; ประกาศ PDPC มาตรการความปลอดภัย 2565; พ.ร.ฎ. วิธีการแบบปลอดภัย 2553 | Y34: CIS Controls v8.1; CSA CCM v4 / STAR; ISO/IEC 27001:2022; ISO/IEC 27002:2022; ISO/IEC 27017; ISO/IEC 27018; ISO/IEC 27701; ISO/IEC 29100; OWASP ASVS 5.0; OWASP Top 10:2025; PCI DSS v4.0 | Z34: C-LOG-CENTRAL | AA34: C-LOG-90, C-PRV-BREACH, C-PRV-MEASURE, C-PRV-MINIMIZE | AB34: 5 | AC34: Splunk Forwarder; Datadog Agent; Cribl Stream | AE34: Logstash ค่าปริยาย heap 1 GB (แนะนำ 4-8 GB เมื่อ throughput สูง); ทุก pipeline worker กิน RAM เพิ่ม | AF34: ถ้า RAM จำกัด ให้ตัด Logstash ออกและใช้ Filebeat -> Elasticsearch Ingest Pipeline โดยตรง ประหยัดได้ 1.5-4 GB ต่อเครื่อง
A35: kibana | B35: Kibana (Log Visualization / Audit Review) | C35: 5 | D35: Log UI | E35: Core | F35: oss | G35: SSPL / Elastic License | H35: 1 | I35: 2 | J35: 10 | K35: 2 | L35: 4 | M35: 30 | N35: 1 | O35: 1.2 | P35: resident | Q35: resident | R35: =INDEX('02_Freq_Weight'!$E$3:$E$9,MATCH(Q35,'02_Freq_Weight'!$A$3:$A$9,0)) | S35: 0.05 | T35: 90 | U35: 0.05 | V35: 0.15 | W35: log_mgmt, audit_trail, siem_alert | X35: พ.ร.บ. คอมพิวเตอร์ 2550/2560; พ.ร.บ. ไซเบอร์ 2562; มสพร. 11-2566 เว็บไซต์ภาครัฐ 3.0; มาตรฐานข้อมูลเปิดภาครัฐ; พ.ร.บ. ปฏิบัติราชการทางอิเล็กทรอนิกส์ 2565; ขมธอ. ลายมือชื่อ/เอกสารอิเล็กทรอนิกส์; ขมธอ. ความมั่นคงปลอดภัยสารสนเทศ; ITA (ป.ป.ช.); มาตรฐานคลาวด์ 2567; มาตรฐานขั้นต่ำ 2566; กรอบมาตรฐานไซเบอร์ 2564; มาตรฐานเว็บไซต์ 2568; PDPA 2562; ประกาศ PDPC แจ้งเหตุละเมิด 2565; ประกาศ PDPC มาตรการความปลอดภัย 2565; พ.ร.ฎ. วิธีการแบบปลอดภัย 2553 | Y35: CIS Controls v8.1; CSA CCM v4 / STAR; ISO 22301:2019; ISO/IEC 27001:2022; ISO/IEC 27002:2022; ISO/IEC 27017; ISO/IEC 27018; ISO/IEC 27701; ISO/IEC 29100; ISO/IEC 42001:2023; NIST SP 800-207; NIST SP 800-53r5; NIST CSF 2.0; NIST SSDF (SP 800-218); OWASP ASVS 5.0; OWASP Top 10:2025; PCI DSS v4.0; SLSA v1.0; SOC 2 (TSC) | Z35: C-LOG-90, C-LOG-AUDIT, C-LOG-CENTRAL | AA35: C-LOG-NOTIFY, C-LOG-SIEM, C-OPS-BCP, C-PRV-BREACH, C-PRV-MEASURE, C-PRV-MINIMIZE, C-SDLC-TRACE, C-WEB-SELF | AB35: 11 | AC35: Splunk Dashboards; Datadog; Grafana Enterprise | AE35: Kibana เป็น Node.js app ค่าปริยาย heap ~1 GB (ปรับผ่าน NODE_OPTIONS --max-old-space-size) | AF35: ใช้ตรวจ Access Log และ Audit Log ก่อนกด Approve ขึ้น Production ซึ่งเป็นหลักฐานประกอบการตรวจสอบระบบตาม พ.ร.บ. ไซเบอร์ ม.54-57
A36: filebeat | B36: Filebeat (Log Shipper ต่อเครื่อง) | C36: 5 | D36: Log Agent | E36: Core | F36: oss | G36: SSPL / Elastic License | H36: 1 | I36: 1 | J36: 5 | K36: 1 | L36: 1 | M36: 10 | N36: 1 | O36: 0.15 | P36: resident | Q36: resident | R36: =INDEX('02_Freq_Weight'!$E$3:$E$9,MATCH(Q36,'02_Freq_Weight'!$A$3:$A$9,0)) | S36: 0.02 | T36: 7 | U36: 0.05 | V36: 0.2 | W36: log_mgmt | X36: พ.ร.บ. คอมพิวเตอร์ 2550/2560; มสพร. 11-2566 เว็บไซต์ภาครัฐ 3.0; ขมธอ. ความมั่นคงปลอดภัยสารสนเทศ; มาตรฐานคลาวด์ 2567; มาตรฐานขั้นต่ำ 2566; มาตรฐานเว็บไซต์ 2568; PDPA 2562; ประกาศ PDPC แจ้งเหตุละเมิด 2565; ประกาศ PDPC มาตรการความปลอดภัย 2565; พ.ร.ฎ. วิธีการแบบปลอดภัย 2553 | Y36: CIS Controls v8.1; CSA CCM v4 / STAR; ISO/IEC 27001:2022; ISO/IEC 27002:2022; ISO/IEC 27017; ISO/IEC 27018; ISO/IEC 27701; ISO/IEC 29100; OWASP ASVS 5.0; OWASP Top 10:2025; PCI DSS v4.0 | Z36: C-LOG-CENTRAL | AA36: C-LOG-90, C-PRV-BREACH, C-PRV-MEASURE, C-PRV-MINIMIZE | AB36: 5 | AC36: Splunk Universal Forwarder; Datadog Agent; Fluent Bit | AE36: Filebeat เป็น Go binary กิน RAM 50-150 MB ต่อ instance; ต้องลงทุกเครื่องที่ต้องการเก็บ log | AF36: ทั้ง 2 โครงการใช้ Filebeat ส่ง Log เข้า Elasticsearch แบบ Real-time; ต้องนับ 1 instance ต่อ 1 VM ในการคำนวณ (เล็กแต่คูณจำนวนเครื่อง)
A37: wazuh | B37: Wazuh (SIEM / HIDS + Alerting) | C37: 5 | D37: SIEM | E37: Optional | F37: oss | G37: GPL-2.0 | H37: 4 | I37: 8 | J37: 50 | K37: 8 | L37: 16 | M37: 300 | N37: 1 | O37: 6 | P37: resident | Q37: resident | R37: =INDEX('02_Freq_Weight'!$E$3:$E$9,MATCH(Q37,'02_Freq_Weight'!$A$3:$A$9,0)) | S37: 1 | T37: 90 | U37: 0.4 | V37: 0.3 | W37: siem_alert, log_mgmt, audit_trail, runtime_security, config_mgmt | X37: พ.ร.บ. คอมพิวเตอร์ 2550/2560; พ.ร.บ. ไซเบอร์ 2562; มสพร. 11-2566 เว็บไซต์ภาครัฐ 3.0; มาตรฐานข้อมูลเปิดภาครัฐ; พ.ร.บ. ปฏิบัติราชการทางอิเล็กทรอนิกส์ 2565; ขมธอ. การใช้บริการคลาวด์; ขมธอ. ลายมือชื่อ/เอกสารอิเล็กทรอนิกส์; ขมธอ. ความมั่นคงปลอดภัยสารสนเทศ; ITA (ป.ป.ช.); มาตรฐานคลาวด์ 2567; มาตรฐานขั้นต่ำ 2566; กรอบมาตรฐานไซเบอร์ 2564; มาตรฐานเว็บไซต์ 2568; PDPA 2562; ประกาศ PDPC แจ้งเหตุละเมิด 2565; ประกาศ PDPC มาตรการความปลอดภัย 2565; พ.ร.ฎ. วิธีการแบบปลอดภัย 2553 | Y37: CIS Benchmarks; CIS Controls v8.1; CSA CCM v4 / STAR; ISO 22301:2019; ISO/IEC 27001:2022; ISO/IEC 27002:2022; ISO/IEC 27017; ISO/IEC 27018; ISO/IEC 27701; ISO/IEC 29100; ISO/IEC 42001:2023; NIST SP 800-207; NIST SP 800-53r5; NIST CSF 2.0; NIST SSDF (SP 800-218); OWASP ASVS 5.0; OWASP Top 10:2025; PCI DSS v4.0; SLSA v1.0; SOC 2 (TSC) | Z37: C-LOG-90, C-LOG-AUDIT, C-LOG-CENTRAL, C-OPS-HARDEN, C-OPS-RUNTIME | AA37: C-AI-DRIFT, C-IAM-LEAST, C-IAM-REMOTE, C-LOG-NOTIFY, C-LOG-SIEM, C-OPS-BCP, C-PRV-BREACH, C-PRV-MEASURE, C-PRV-MINIMIZE, C-SDLC-TRACE, C-WEB-SELF | AB37: 16 | AC37: Splunk Enterprise Security; Microsoft Sentinel; IBM QRadar; Elastic Security | AE37: Wazuh docs: server ขั้นต่ำ 2 vCPU / 4 GB สำหรับ < 25 agents แต่แนะนำ 4 vCPU / 8 GB ขึ้นไปเมื่อรวม Indexer; Indexer เป็น OpenSearch จึงกิน RAM แบบเดียวกับ Elasticsearch | AF37: จำเป็นสำหรับ CYBER2562-R2 (เฝ้าระวัง + รายงาน สกมช. ทันที) และ PDPA-R2 (แจ้งเหตุใน 72 ชม.); ถ้ามี ELK อยู่แล้วให้พิจารณา Elastic Security แทนเพื่อไม่ต้องรัน OpenSearch ซ้อน
A38: vault | B38: HashiCorp Vault / OpenBao (Secret Management) | C38: 5 | D38: Secret Management | E38: Optional | F38: oss | G38: BUSL-1.1 / MPL-2.0 | H38: 2 | I38: 4 | J38: 20 | K38: 2 | L38: 4 | M38: 60 | N38: 1 | O38: 1 | P38: resident | Q38: resident | R38: =INDEX('02_Freq_Weight'!$E$3:$E$9,MATCH(Q38,'02_Freq_Weight'!$A$3:$A$9,0)) | S38: 0.05 | T38: 2555 | U38: 0.1 | V38: 0.15 | W38: secret_mgmt, iam_mfa, audit_trail | X38: พ.ร.บ. คอมพิวเตอร์ 2550/2560; พ.ร.บ. ไซเบอร์ 2562; มสพร. 11-2566 เว็บไซต์ภาครัฐ 3.0; มาตรฐานข้อมูลเปิดภาครัฐ; พ.ร.บ. ปฏิบัติราชการทางอิเล็กทรอนิกส์ 2565; ขมธอ. การใช้บริการคลาวด์; ขมธอ. ลายมือชื่อ/เอกสารอิเล็กทรอนิกส์; ขมธอ. ความมั่นคงปลอดภัยสารสนเทศ; ITA (ป.ป.ช.); มาตรฐานคลาวด์ 2567; มาตรฐานขั้นต่ำ 2566; กรอบมาตรฐานไซเบอร์ 2564; มาตรฐานเว็บไซต์ 2568; PDPA 2562; ประกาศ PDPC มาตรการความปลอดภัย 2565; พ.ร.ฎ. วิธีการแบบปลอดภัย 2553 | Y38: CIS Benchmarks; CIS Controls v8.1; CSA CCM v4 / STAR; ISO 22301:2019; ISO/IEC 27001:2022; ISO/IEC 27002:2022; ISO/IEC 27017; ISO/IEC 27018; ISO/IEC 27701; ISO/IEC 29100; ISO/IEC 42001:2023; NIST SP 800-207; NIST SP 800-53r5; NIST SP 800-63B; NIST CSF 2.0; NIST SSDF (SP 800-218); OWASP API Top 10:2023; OWASP ASVS 5.0; OWASP MASVS; OWASP Top 10:2025; SLSA v1.0; SOC 2 (TSC) | Z38: C-CRY-KEY, C-IAM-MFA, C-LOG-AUDIT | AA38: C-APP-AUTHN, C-IAM-LEAST, C-IAM-REMOTE, C-LOG-90, C-OPS-BCP, C-PRV-MEASURE, C-SDLC-SECRET, C-SDLC-TRACE, C-WEB-SELF | AB38: 12 | AC38: HashiCorp Vault Enterprise; Azure Key Vault; AWS Secrets Manager; CyberArk Conjur | AD38: OpenBao; Infisical; SOPS + age; Sealed Secrets | AE38: Vault แนะนำ 2 vCPU / 4-8 GB สำหรับ production ขนาดเล็ก (มี in-memory cache + audit log); ต้องมี storage backend (Raft/Consul) | AF38: ตอบ PDPA-R1 (การเข้ารหัส + Key Rotation) และ OWASP-A04; ห้ามเก็บ Credential ใน Jenkins Credentials อย่างเดียวเพราะไม่มี Rotation/Lease — Vault ต้องเปิด Audit Device ตลอดเวลา
A39: k3s-control | B39: Kubernetes / K3s Control Plane (ต่อ 1 Node) | C39: 6 | D39: Container Orchestration | E39: Core | F39: oss | G39: Apache-2.0 | H39: 2 | I39: 4 | J39: 40 | K39: 4 | L39: 8 | M39: 100 | N39: 1 | O39: 2.5 | P39: resident | Q39: resident | R39: =INDEX('02_Freq_Weight'!$E$3:$E$9,MATCH(Q39,'02_Freq_Weight'!$A$3:$A$9,0)) | S39: 0.3 | T39: 90 | U39: 0.15 | V39: 0.2 | W39: orchestration, deploy_strategy, iam_mfa | X39: พ.ร.บ. ไซเบอร์ 2562; มสพร. 11-2566 เว็บไซต์ภาครัฐ 3.0; ขมธอ. การใช้บริการคลาวด์; ขมธอ. ความมั่นคงปลอดภัยสารสนเทศ; มาตรฐานคลาวด์ 2567; มาตรฐานขั้นต่ำ 2566; มาตรฐานเว็บไซต์ 2568; PDPA 2562; ประกาศ PDPC มาตรการความปลอดภัย 2565; พ.ร.ฎ. วิธีการแบบปลอดภัย 2553 | Y39: CIS Benchmarks; CIS Controls v8.1; CSA CCM v4 / STAR; ISO/IEC 27001:2022; ISO/IEC 27017; ISO/IEC 27018; ISO/IEC 27701; ISO/IEC 29100; NIST SP 800-207; NIST SP 800-53r5; NIST SP 800-63B; OWASP API Top 10:2023; OWASP ASVS 5.0; OWASP MASVS; OWASP Top 10:2025; SOC 2 (TSC) | Z39: C-IAM-MFA, C-OPS-DEPLOY | AA39: C-APP-AUTHN, C-IAM-LEAST, C-IAM-REMOTE, C-PRV-MEASURE | AB39: 6 | AC39: Red Hat OpenShift; Rancher Enterprise; VMware Tanzu; Google GKE Enterprise; Azure AKS | AD39: MicroK8s; K0s; Docker Swarm; Nomad; Docker Compose (UAT เท่านั้น) | AE39: K3s docs: server node ขั้นต่ำ 2 vCPU / 2 GB (แนะนำ 4 GB); kubeadm control plane ขั้นต่ำ 2 vCPU / 2 GB แต่ etcd + apiserver ที่โหลดจริงควรมี 4 GB ขึ้นไป | AF39: ถ้าโครงการยังใช้ Docker Compose อยู่ (เช่น UAT ของทั้ง 2 โครงการ) ยังไม่ต้องนับส่วนนี้ — แต่ต้องเผื่อไว้ในแผน Production เพราะ Blueprint ระบุ Container Orchestration เป็น Core
A40: argocd | B40: Argo CD / Flux (GitOps Continuous Delivery) | C40: 6 | D40: Deployment Strategy | E40: Core | F40: oss | G40: Apache-2.0 | H40: 2 | I40: 4 | J40: 20 | K40: 4 | L40: 8 | M40: 60 | N40: 1 | O40: 2 | P40: resident | Q40: resident | R40: =INDEX('02_Freq_Weight'!$E$3:$E$9,MATCH(Q40,'02_Freq_Weight'!$A$3:$A$9,0)) | S40: 0.1 | T40: 365 | U40: 0.1 | V40: 0.15 | W40: deploy_strategy, audit_trail, quality_gate, version_tag | X40: พ.ร.บ. คอมพิวเตอร์ 2550/2560; พ.ร.บ. ไซเบอร์ 2562; มาตรฐานข้อมูลเปิดภาครัฐ; พ.ร.บ. ปฏิบัติราชการทางอิเล็กทรอนิกส์ 2565; ขมธอ. ลายมือชื่อ/เอกสารอิเล็กทรอนิกส์; ITA (ป.ป.ช.); มาตรฐานขั้นต่ำ 2566; กรอบมาตรฐานไซเบอร์ 2564; มาตรฐานเว็บไซต์ 2568; PDPA 2562 | Y40: CIS Controls v8.1; ISO 22301:2019; ISO/IEC 27001:2022; ISO/IEC 27018; ISO/IEC 27034; ISO/IEC 27701; ISO/IEC 42001:2023; NIST SP 800-53r5; NIST CSF 2.0; NIST SSDF (SP 800-218); OWASP SAMM 2; OWASP Top 10:2025; SLSA v1.0; SOC 2 (TSC) | Z40: C-LOG-AUDIT | AA40: C-AI-GOV, C-LOG-90, C-OPS-BCP, C-OPS-DEPLOY, C-SC-PIN, C-SDLC-REVIEW, C-SDLC-THREAT, C-SDLC-TRACE, C-WEB-SELF | AB40: 10 | AC40: Harness CD; Spinnaker Enterprise; GitLab Premium Auto DevOps; LaunchDarkly | AE40: Argo CD ประกอบด้วย api-server, repo-server, application-controller, Redis; รวมกันขั้นต่ำ ~2 vCPU / 2-4 GB สำหรับ < 50 applications | AF40: ให้ Git เป็น Single Source of Truth = ได้ Audit Trail และ Rollback ฟรีตาม CORE-R2; Argo Rollouts เพิ่ม Canary/Blue-Green ได้ด้วย resource เพิ่มเพียง ~0.5 vCPU / 0.5 GB
...

Sheet 02_Freq_Weight
A1: 02 — ชั้นความถี่การรัน และการแปลงเป็นน้ำหนัก (Duty Weight) | C1: w_solo = w_base + w_span x activity_index -> ช่วงเดี่ยว 20% - 60%; บน VM ใช้ w_max(n) ladder
A2: freq_id | B2: ความถี่การรัน | C2: ครั้ง/วัน | D2: activity_index | E2: น้ำหนัก w | F2: เหตุผล / ข้อควรระวัง
A3: resident | B3: รันค้างตลอดเวลา 24/7 (Resident Daemon) | C3: ตลอดเวลา | D3: 1 | E3: ='05_Params'!$B$9+'05_Params'!$B$10*D3 | F3: น้ำหนักสูงสุด 60% เมื่ออยู่เครื่องเดียว ลดตามจำนวนเครื่องมือร่วมเครื่องลงถึงพื้น 20%
A4: per_commit | B4: ทุก Commit / Push (10-30 ครั้ง/วัน) | C4: 10-30 | D4: 0.8 | E4: ='05_Params'!$B$9+'05_Params'!$B$10*D4 | F4: Trigger บ่อย ยังซ้อนทับได้ แต่ถูกจำกัดด้วยเพดาน w_max(n) ของเครื่องนั้น
A5: per_build | B5: ทุก Build / Merge (5-15 ครั้ง/วัน) | C5: 5-15 | D5: 0.65 | E5: ='05_Params'!$B$9+'05_Params'!$B$10*D5 | F5: รันเป็นช่วง ๆ ระหว่างวันทำงาน มีโอกาสซ้อนทับปานกลาง
A6: per_pr | B6: ทุก Pull Request / Quality Gate (3-10 ครั้ง/วัน) | C6: 3-10 | D6: 0.55 | E6: ='05_Params'!$B$9+'05_Params'!$B$10*D6 | F6: ผูกกับรอบ Review ของทีม
A7: nightly | B7: รอบกลางคืน / วันละครั้ง (Nightly) | C7: 1 | D7: 0.35 | E7: ='05_Params'!$B$9+'05_Params'!$B$10*D7 | F7: เช่น DAST Full Scan, Dependency-Check ที่ใช้เวลานาน ย้ายไปรันหลังบ้าน
A8: weekly | B8: รายสัปดาห์ (1-2 ครั้ง/สัปดาห์) | C8: 0.15-0.3 | D8: 0.15 | E8: ='05_Params'!$B$9+'05_Params'!$B$10*D8 | F8: เช่น Performance/Load Test รอบใหญ่, License Audit
A9: on_demand | B9: ตามคำสั่ง / รอบ Release (ไม่กี่ครั้ง/เดือน) | C9: <0.1 | D9: 0 | E9: ='05_Params'!$B$9+'05_Params'!$B$10*D9 | F9: บวกที่ 20% ซึ่งเป็นค่าต่ำสุดของช่วงที่กำหนด เพราะยังต้องกันที่ไว้ให้รันได้
A11: ช่วง 20-60%: เครื่องมือตามคำสั่งบวกที่ 20% (กันที่ไว้ให้รันได้) เครื่องมือ resident บนเครื่องเดียวบวกที่ 60% แล้วลดตามจำนวนเครื่องมือร่วมเครื่อง ลงถึงพื้น 20% เมื่อมี 8 ตัวขึ้นไป

Sheet 03_Colocation_Calc
A1: 03 — เครื่องคำนวณกรณีเครื่องเดียวแชร์หลายเครื่องมือ (Co-location Input) | C1: ใส่ 1 ในคอลัมน์ VM ที่ต้องการติดตั้งเครื่องมือนั้น (0 หรือว่าง = ไม่ติดตั้ง) แล้วดูผลที่ชีท 04 · ค่าเริ่มต้นคือผังอ้างอิง 6 เครื่องสำหรับภาครัฐ — ผังแบบอื่นดูที่ชีท 10 | T1: EDGE-01 | U1: CI-CONTROL-01 | V1: BUILD-AGENT-01 | W1: SEC-TEST-01 | X1: STORE-LOG-01 | Y1: DEPLOY-MON-01 | Z1: (ว่าง) VM07 | AA1: (ว่าง) VM08 | AB1: (ว่าง) VM09 | AC1: (ว่าง) VM10
A2: tool_id | B2: เครื่องมือ | C2: Stage | D2: conc_group | E2: freq_id | F2: min vCPU | G2: min RAM | H2: Idle RAM | I2: Resident | J2: Install GB | K2: GB/วัน | L2: Retention | M2: Index OH | N2: Growth/ปี | O2: น้ำหนัก w | P2: Data GB @H1 | Q2: Data GB @H2 | R2: Data GB @H3 | S2: Data GB @H4 | T2: VM01 | U2: VM02 | V2: VM03 | W2: VM04 | X2: VM05 | Y2: VM06 | Z2: VM07 | AA2: VM08 | AB2: VM09 | AC2: VM10
A3: gitlab-ce | B3: GitLab Community Edition (Self-hosted Git) | C3: 1 | D3: resident | E3: resident | F3: 4 | G3: 8 | H3: 5 | I3: 1 | J3: 40 | K3: 0.05 | L3: 3650 | M3: 0.2 | N3: 0.25 | O3: =INDEX('02_Freq_Weight'!$E$3:$E$9,MATCH(E3,'02_Freq_Weight'!$A$3:$A$9,0)) | P3: =$K3*'05_Params'!$B$4*POWER(1+$N3,'05_Params'!$B$13/12)*MIN($L3,'05_Params'!$B$13*30.44)*(1+$M3) | Q3: =$K3*'05_Params'!$B$4*POWER(1+$N3,'05_Params'!$B$14/12)*MIN($L3,'05_Params'!$B$14*30.44)*(1+$M3) | R3: =$K3*'05_Params'!$B$4*POWER(1+$N3,'05_Params'!$B$15/12)*MIN($L3,'05_Params'!$B$15*30.44)*(1+$M3) | S3: =$K3*'05_Params'!$B$4*POWER(1+$N3,'05_Params'!$B$16/12)*MIN($L3,'05_Params'!$B$16*30.44)*(1+$M3) | T3: 0 | U3: 0 | V3: 0 | W3: 0 | X3: 0 | Y3: 0 | Z3: 0 | AA3: 0 | AB3: 0 | AC3: 0
A4: gitea | B4: Gitea / Forgejo (Lightweight Git) | C4: 1 | D4: resident | E4: resident | F4: 1 | G4: 1 | H4: 0.5 | I4: 1 | J4: 10 | K4: 0.02 | L4: 3650 | M4: 0.1 | N4: 0.25 | O4: =INDEX('02_Freq_Weight'!$E$3:$E$9,MATCH(E4,'02_Freq_Weight'!$A$3:$A$9,0)) | P4: =$K4*'05_Params'!$B$4*POWER(1+$N4,'05_Params'!$B$13/12)*MIN($L4,'05_Params'!$B$13*30.44)*(1+$M4) | Q4: =$K4*'05_Params'!$B$4*POWER(1+$N4,'05_Params'!$B$14/12)*MIN($L4,'05_Params'!$B$14*30.44)*(1+$M4) | R4: =$K4*'05_Params'!$B$4*POWER(1+$N4,'05_Params'!$B$15/12)*MIN($L4,'05_Params'!$B$15*30.44)*(1+$M4) | S4: =$K4*'05_Params'!$B$4*POWER(1+$N4,'05_Params'!$B$16/12)*MIN($L4,'05_Params'!$B$16*30.44)*(1+$M4) | T4: 0 | U4: 1 | V4: 0 | W4: 0 | X4: 0 | Y4: 0 | Z4: 0 | AA4: 0 | AB4: 0 | AC4: 0
A5: github-actions-runner | B5: GitHub Actions Self-hosted Runner | C5: 1 | D5: ci_seq | E5: per_commit | F5: 2 | G5: 4 | H5: 0.2 | I5: 0 | J5: 60 | K5: 0.6 | L5: 30 | M5: 0.05 | N5: 0.2 | O5: =INDEX('02_Freq_Weight'!$E$3:$E$9,MATCH(E5,'02_Freq_Weight'!$A$3:$A$9,0)) | P5: =$K5*'05_Params'!$B$4*POWER(1+$N5,'05_Params'!$B$13/12)*MIN($L5,'05_Params'!$B$13*30.44)*(1+$M5) | Q5: =$K5*'05_Params'!$B$4*POWER(1+$N5,'05_Params'!$B$14/12)*MIN($L5,'05_Params'!$B$14*30.44)*(1+$M5) | R5: =$K5*'05_Params'!$B$4*POWER(1+$N5,'05_Params'!$B$15/12)*MIN($L5,'05_Params'!$B$15*30.44)*(1+$M5) | S5: =$K5*'05_Params'!$B$4*POWER(1+$N5,'05_Params'!$B$16/12)*MIN($L5,'05_Params'!$B$16*30.44)*(1+$M5) | T5: 0 | U5: 0 | V5: 0 | W5: 0 | X5: 0 | Y5: 0 | Z5: 0 | AA5: 0 | AB5: 0 | AC5: 0
A6: jenkins-master | B6: Jenkins Master / Controller | C6: 1 | D6: resident | E6: resident | F6: 2 | G6: 4 | H6: 2 | I6: 1 | J6: 20 | K6: 0.15 | L6: 180 | M6: 0.1 | N6: 0.15 | O6: =INDEX('02_Freq_Weight'!$E$3:$E$9,MATCH(E6,'02_Freq_Weight'!$A$3:$A$9,0)) | P6: =$K6*'05_Params'!$B$4*POWER(1+$N6,'05_Params'!$B$13/12)*MIN($L6,'05_Params'!$B$13*30.44)*(1+$M6) | Q6: =$K6*'05_Params'!$B$4*POWER(1+$N6,'05_Params'!$B$14/12)*MIN($L6,'05_Params'!$B$14*30.44)*(1+$M6) | R6: =$K6*'05_Params'!$B$4*POWER(1+$N6,'05_Params'!$B$15/12)*MIN($L6,'05_Params'!$B$15*30.44)*(1+$M6) | S6: =$K6*'05_Params'!$B$4*POWER(1+$N6,'05_Params'!$B$16/12)*MIN($L6,'05_Params'!$B$16*30.44)*(1+$M6) | T6: 0 | U6: 1 | V6: 0 | W6: 0 | X6: 0 | Y6: 0 | Z6: 0 | AA6: 0 | AB6: 0 | AC6: 0
A7: jenkins-agent | B7: Jenkins Agent / Build Executor (ต่อ 1 Executor) | C7: 1 | D7: resident | E7: per_commit | F7: 2 | G7: 4 | H7: 0.3 | I7: 0 | J7: 60 | K7: 0.8 | L7: 7 | M7: 0.05 | N7: 0.2 | O7: =INDEX('02_Freq_Weight'!$E$3:$E$9,MATCH(E7,'02_Freq_Weight'!$A$3:$A$9,0)) | P7: =$K7*'05_Params'!$B$4*POWER(1+$N7,'05_Params'!$B$13/12)*MIN($L7,'05_Params'!$B$13*30.44)*(1+$M7) | Q7: =$K7*'05_Params'!$B$4*POWER(1+$N7,'05_Params'!$B$14/12)*MIN($L7,'05_Params'!$B$14*30.44)*(1+$M7) | R7: =$K7*'05_Params'!$B$4*POWER(1+$N7,'05_Params'!$B$15/12)*MIN($L7,'05_Params'!$B$15*30.44)*(1+$M7) | S7: =$K7*'05_Params'!$B$4*POWER(1+$N7,'05_Params'!$B$16/12)*MIN($L7,'05_Params'!$B$16*30.44)*(1+$M7) | T7: 0 | U7: 0 | V7: 1 | W7: 0 | X7: 0 | Y7: 0 | Z7: 0 | AA7: 0 | AB7: 0 | AC7: 0
A8: argo-workflows | B8: Argo Workflows (CNCF Graduated) | C8: 1 | D8: resident | E8: resident | F8: 1 | G8: 2 | H8: 1 | I8: 1 | J8: 10 | K8: 0.15 | L8: 90 | M8: 0.1 | N8: 0.2 | O8: =INDEX('02_Freq_Weight'!$E$3:$E$9,MATCH(E8,'02_Freq_Weight'!$A$3:$A$9,0)) | P8: =$K8*'05_Params'!$B$4*POWER(1+$N8,'05_Params'!$B$13/12)*MIN($L8,'05_Params'!$B$13*30.44)*(1+$M8) | Q8: =$K8*'05_Params'!$B$4*POWER(1+$N8,'05_Params'!$B$14/12)*MIN($L8,'05_Params'!$B$14*30.44)*(1+$M8) | R8: =$K8*'05_Params'!$B$4*POWER(1+$N8,'05_Params'!$B$15/12)*MIN($L8,'05_Params'!$B$15*30.44)*(1+$M8) | S8: =$K8*'05_Params'!$B$4*POWER(1+$N8,'05_Params'!$B$16/12)*MIN($L8,'05_Params'!$B$16*30.44)*(1+$M8) | T8: 0 | U8: 0 | V8: 0 | W8: 0 | X8: 0 | Y8: 0 | Z8: 0 | AA8: 0 | AB8: 0 | AC8: 0
A9: opa-conftest | B9: Open Policy Agent / Conftest (Policy-as-Code Gate) | C9: 1 | D9: ci_seq | E9: per_pr | F9: 1 | G9: 1 | H9: 0 | I9: 0 | J9: 5 | K9: 0.01 | L9: 90 | M9: 0.05 | N9: 0.1 | O9: =INDEX('02_Freq_Weight'!$E$3:$E$9,MATCH(E9,'02_Freq_Weight'!$A$3:$A$9,0)) | P9: =$K9*'05_Params'!$B$4*POWER(1+$N9,'05_Params'!$B$13/12)*MIN($L9,'05_Params'!$B$13*30.44)*(1+$M9) | Q9: =$K9*'05_Params'!$B$4*POWER(1+$N9,'05_Params'!$B$14/12)*MIN($L9,'05_Params'!$B$14*30.44)*(1+$M9) | R9: =$K9*'05_Params'!$B$4*POWER(1+$N9,'05_Params'!$B$15/12)*MIN($L9,'05_Params'!$B$15*30.44)*(1+$M9) | S9: =$K9*'05_Params'!$B$4*POWER(1+$N9,'05_Params'!$B$16/12)*MIN($L9,'05_Params'!$B$16*30.44)*(1+$M9) | T9: 0 | U9: 1 | V9: 0 | W9: 0 | X9: 0 | Y9: 0 | Z9: 0 | AA9: 0 | AB9: 0 | AC9: 0
A10: nginx-gateway | B10: Nginx (Reverse Proxy / Webhook Relay) | C10: 1 | D10: resident | E10: resident | F10: 1 | G10: 1 | H10: 0.3 | I10: 1 | J10: 10 | K10: 0.1 | L10: 90 | M10: 0.1 | N10: 0.2 | O10: =INDEX('02_Freq_Weight'!$E$3:$E$9,MATCH(E10,'02_Freq_Weight'!$A$3:$A$9,0)) | P10: =$K10*'05_Params'!$B$4*POWER(1+$N10,'05_Params'!$B$13/12)*MIN($L10,'05_Params'!$B$13*30.44)*(1+$M10) | Q10: =$K10*'05_Params'!$B$4*POWER(1+$N10,'05_Params'!$B$14/12)*MIN($L10,'05_Params'!$B$14*30.44)*(1+$M10) | R10: =$K10*'05_Params'!$B$4*POWER(1+$N10,'05_Params'!$B$15/12)*MIN($L10,'05_Params'!$B$15*30.44)*(1+$M10) | S10: =$K10*'05_Params'!$B$4*POWER(1+$N10,'05_Params'!$B$16/12)*MIN($L10,'05_Params'!$B$16*30.44)*(1+$M10) | T10: 1 | U10: 0 | V10: 0 | W10: 0 | X10: 0 | Y10: 0 | Z10: 0 | AA10: 0 | AB10: 0 | AC10: 0
